Workbook
Name _Toc158958007: 'QMS - SS'!$A$1
Name _Toc158958008: 'QMS - SS'!$B$1
Name _Toc158958009: 'QMS - SS'!$B$2
Name _Toc158958010: 'QMS - SS'!$D$2
Name _Toc158958012: 'QMS - SS'!$B$3
Name _Toc158958013: 'QMS - SS'!$C$3
Name _Toc158958014: 'QMS - SS'!$D$3
Name _Toc158958015: 'QMS - SS'!$E$3

Sheet Input
A1: Input | B1: Unit | C1: Input | E1: Unit | F1: Factor | G1: Value
A2: Insulation Density | B2: Kg/m^3 | C2: 200
A3: Water Density | B3: Kg/m^3 | C3: 1000
A4: Young's Modules (E) | B4: N/mm^2 | C4: 176000 | E4: PSI | F4: 145.04 | G4: =F4*C4 -> 25527040 | M4: B31.1 Check
A5: Allowable Deflection | B5: mm | C5: 6 | E5: in | F5: =1/25.4 -> 0.039370079 | G5: =F5*C5 -> 0.23622047 | M5: 40 | N5: =137.4/40 -> 3.435 | O5: =1/N5 -> 0.29112082 | P5: QMS
A6: Allowable Bendig Stress | B6: N/mm^2 | C6: 34 | E6: PSI | F6: 145.04 | G6: =F6*C6 -> 4931.36 | H6: Basis ~1/3 of 20000 PSI (137.4 N/mm^2) | M6: 25 | N6: =137.4/25 -> 5.496 | O6: =1/N6 -> 0.18195051 | P6: DUQM
A7: Bearing Length (d) | B7: mm | C7: 100 | M7: 30 | N7: =137.4/30 -> 4.58 | O7: =1/N7 -> 0.21834061 | P7: GC-32
A8: Bearing Width (b) | B8: mm | C8: 16.5 | H8: for 42" pipe and directly proportional for other size
A9: S=0.67 Sh | B9: N/mm^2 | C9: 67
A12: Beam Type | B12: Span Factor in Deflection | C12: Span Factor in Stress
A13: Simply Supported | B13: =384/5 -> 76.8 | C13: 8
A14: Continuous | B14: 185 | C14: 8
A15: Fixed | B15: 384 | C15: 12
A16: Average method | B16: =384/3 -> 128 | C16: 10

Sheet Bare+Vapour
A1: Pipe Size | B1: Pipe OD | C1: Sch | D1: Thk | E1: Ins. Thk | F1: Pipe Wt | G1: Ins. Wt | H1: Water Wt | I1: Bearing width | J1: M.I | K1: Span per | L1: Simply Supported BS:3974 | N1: Continuous Beam BS:3974 | P1: Continuous Beam Span (Civil Hand Book) | R1: Fixed Beam Span (Civil Hand Book) | T1: Average Span (Kellog) | V1: Average Span (LC Peng) | X1: Least of All | Y1: FEED | Z1: QMS | AA1: QMS | AB1: QMS Vs | AC1: FEED Vs | AD1: FEED Vs
D2: mm | E2: mm | F2: N/m | G2: N/m | H2: N/m | I2: mm | J2: cm4 | K2: Indentation | L2: Deflection (Span in m) | M2: Stress (Span in m) | N2: Deflection (Span in m) | O2: Stress (Span in m) | P2: Deflection (Span in m) | Q2: Stress (Span in m) | R2: Deflection (Span in m) | S2: Stress (Span in m) | T2: Deflection (Span in m) | U2: Stress (Span in m) | V2: Deflection (Span in m) | W2: Stress (Span in m) | X2: Span (m) | Y2: Span | Z2: Span | AA2: Rack Span | AB2: Least | AC2: Least | AD2: BS-Cont, Beam
A3: 0.75 | B3: 26.67 | C3: Sch 40 | D3: 2.87 | E3: 40 | F3: =((3.1428*(B3^2-(B3-2*D3)^2)/4)*7.85/1000)*9.81 -> 16.531576 | G3: =(3.14*(B3+E3)*E3*Input!C$2/1000000)*9.81 -> 16.429301 | H3: =((3.14*(B3-2*D3)^2)/4*Input!C$3/1000000)*9.81 -> 3.3734721 | I3: =(Input!C$8/1067)*'Bare+Vapour'!B3 -> 0.41242268 | J3: =((3.1428*(B3^4-(B3-(2*D3))^4)/64))/10000 -> 1.5420887 | K3: =(Input!C$9*(Input!C$7+I3)*D3^2)/(0.644*F3*((B3/2)*D3)^0.5) -> 841.37277 | L3: =((384*Input!$C$4*$J3*Input!$C$5)/(5*$F3*100000))^(1/4) -> 2.9492056 | M3: =((160*Input!$C$6*$J3)/(B3*$F3))^0.5 -> 4.3619982 | N3: =((384*Input!$C$4*$J3*Input!$C$5)/(($F3*100000)))^(1/4) -> 4.4100911 | O3: =((240*Input!$C$6*$J3)/($B3*$F3))^0.5 -> 5.342335 | P3: =((185*Input!$G$4*($J3/(2.54)^4)*(Input!$G$5))/($F3*0.00571))^(1/4)*25.4/1000 -> 3.6741948 | Q3: =(((16*Input!$G$6*($J3/(2.54)^4))/(($B3/25.4)*($F3*0.00571)))^0.5)*25.4/1000 -> 4.3620885 | R3: =((384*Input!$G$4*($J3/(2.54)^4)*(Input!$G$5))/($F3*0.00571))^(1/4)*25.4/1000 -> 4.4101367 | S3: =(((24*Input!$G$6*($J3/(2.54)^4))/(($B3/25.4)*($F3*0.00571)))^0.5)*25.4/1000 -> 5.3424455 | T3: =((Input!$G$4*($J3/(2.54)^4)*(Input!$G$5))/(17.1*$F3*0.06854))^(1/4)*0.3048 -> 3.1584533 | U3: =(((20*Input!$G$6*($J3/(2.54)^4))/(($B3/25.4)*($F3*0.00571)))^0.5)*25.4/1000 -> 4.8769632 | V3: =((384*Input!$C$4*$J3*Input!$C$5)/(3*$F3*100000))^(1/4) -> 3.3509446 | W3: =(((200*Input!$C$6*($J3))/($B3*($F3)))^0.5) -> 4.8768623 | X3: =MIN(L3:W3) -> 2.9492056 | Y3: 4.5 | Z3: - | AA3: - | AC3: =Y3/X3 -> 1.5258346 | AD3: =Y3/MIN(N3:O3) -> 1.0203871
A4: 1 | B4: 33.4 | C4: Sch 40 | D4: 3.38 | E4: 40 | F4: =((3.1428*(B4^2-(B4-2*D4)^2)/4)*7.85/1000)*9.81 -> 24.557423 | G4: =(3.14*(B4+E4)*E4*Input!C$2/1000000)*9.81 -> 18.087756 | H4: =((3.14*(B4-2*D4)^2)/4*Input!C$3/1000000)*9.81 -> 5.4652132 | I4: =(Input!C$8/1067)*'Bare+Vapour'!B4 -> 0.51649485 | J4: =((3.1428*(B4^4-(B4-(2*D4))^4)/64))/10000 -> 3.6378636 | K4: =(Input!C$9*(Input!C$7+I4)*D4^2)/(0.644*F4*((B4/2)*D4)^0.5) -> 647.53059 | L4: =((384*Input!$C$4*$J4*Input!$C$5)/(5*$F4*100000))^(1/4) -> 3.310718 | M4: =((160*Input!$C$6*$J4)/(B4*$F4))^0.5 -> 4.9119962 | N4: =((384*Input!$C$4*$J4*Input!$C$5)/(($F4*100000)))^(1/4) -> 4.9506781 | O4: =((240*Input!$C$6*$J4)/($B4*$F4))^0.5 -> 6.0159422 | P4: =((185*Input!$G$4*($J4/(2.54)^4)*(Input!$G$5))/($F4*0.00571))^(1/4)*25.4/1000 -> 4.124576 | Q4: =(((16*Input!$G$6*($J4/(2.54)^4))/(($B4/25.4)*($F4*0.00571)))^0.5)*25.4/1000 -> 4.9120978 | R4: =((384*Input!$G$4*($J4/(2.54)^4)*(Input!$G$5))/($F4*0.00571))^(1/4)*25.4/1000 -> 4.9507293 | S4: =(((24*Input!$G$6*($J4/(2.54)^4))/(($B4/25.4)*($F4*0.00571)))^0.5)*25.4/1000 -> 6.0160666 | T4: =((Input!$G$4*($J4/(2.54)^4)*(Input!$G$5))/(17.1*$F4*0.06854))^(1/4)*0.3048 -> 3.5456152 | U4: =(((20*Input!$G$6*($J4/(2.54)^4))/(($B4/25.4)*($F4*0.00571)))^0.5)*25.4/1000 -> 5.4918923 | V4: =((384*Input!$C$4*$J4*Input!$C$5)/(3*$F4*100000))^(1/4) -> 3.7617019 | W4: =(((200*Input!$C$6*($J4))/($B4*($F4)))^0.5) -> 5.4917787 | X4: =MIN(L4:W4) -> 3.310718 | Y4: 5 | Z4: 3.8 | AA4: 5.7 | AB4: =Z4/MIN(L4:W4) -> 1.1477873 | AC4: =Y4/X4 -> 1.5102464 | AD4: =Y4/MIN(N4:O4) -> 1.0099627
A5: 1.5 | B5: 48.26 | C5: Sch 40 | D5: 3.68 | E5: 50 | F5: =((3.1428*(B5^2-(B5-2*D5)^2)/4)*7.85/1000)*9.81 -> 39.704825 | G5: =(3.14*(B5+E5)*E5*Input!C$2/1000000)*9.81 -> 30.267421 | H5: =((3.14*(B5-2*D5)^2)/4*Input!C$3/1000000)*9.81 -> 12.882059 | I5: =(Input!C$8/1067)*'Bare+Vapour'!B5 -> 0.74628866 | J5: =((3.1428*(B5^4-(B5-(2*D5))^4)/64))/10000 -> 12.895676 | K5: =(Input!C$9*(Input!C$7+I5)*D5^2)/(0.644*F5*((B5/2)*D5)^0.5) -> 379.37418 | L5: =((384*Input!$C$4*$J5*Input!$C$5)/(5*$F5*100000))^(1/4) -> 4.0286217 | M5: =((160*Input!$C$6*$J5)/(B5*$F5))^0.5 -> 6.050708 | N5: =((384*Input!$C$4*$J5*Input!$C$5)/(($F5*100000)))^(1/4) -> 6.0241946 | O5: =((240*Input!$C$6*$J5)/($B5*$F5))^0.5 -> 7.4105736 | P5: =((185*Input!$G$4*($J5/(2.54)^4)*(Input!$G$5))/($F5*0.00571))^(1/4)*25.4/1000 -> 5.0189585 | Q5: =(((16*Input!$G$6*($J5/(2.54)^4))/(($B5/25.4)*($F5*0.00571)))^0.5)*25.4/1000 -> 6.0508332 | R5: =((384*Input!$G$4*($J5/(2.54)^4)*(Input!$G$5))/($F5*0.00571))^(1/4)*25.4/1000 -> 6.0242569 | S5: =(((24*Input!$G$6*($J5/(2.54)^4))/(($B5/25.4)*($F5*0.00571)))^0.5)*25.4/1000 -> 7.4107269 | T5: =((Input!$G$4*($J5/(2.54)^4)*(Input!$G$5))/(17.1*$F5*0.06854))^(1/4)*0.3048 -> 4.3144545 | U5: =(((20*Input!$G$6*($J5/(2.54)^4))/(($B5/25.4)*($F5*0.00571)))^0.5)*25.4/1000 -> 6.7650372 | V5: =((384*Input!$C$4*$J5*Input!$C$5)/(3*$F5*100000))^(1/4) -> 4.577398 | W5: =(((200*Input!$C$6*($J5))/($B5*($F5)))^0.5) -> 6.7648972 | X5: =MIN(L5:W5) -> 4.0286217 | Y5: 6 | Z5: 4.65 | AA5: 6.9 | AB5: =Z5/MIN(L5:W5) -> 1.1542409 | AC5: =Y5/X5 -> 1.4893431 | AD5: =Y5/MIN(N5:O5) -> 0.99598377
A6: 2 | B6: 60.32 | C6: Sch 40 | D6: 3.91 | E6: 50 | F6: =((3.1428*(B6^2-(B6-2*D6)^2)/4)*7.85/1000)*9.81 -> 53.381192 | G6: =(3.14*(B6+E6)*E6*Input!C$2/1000000)*9.81 -> 33.982311 | H6: =((3.14*(B6-2*D6)^2)/4*Input!C$3/1000000)*9.81 -> 21.225468 | I6: =(Input!C$8/1067)*'Bare+Vapour'!B6 -> 0.93278351 | J6: =((3.1428*(B6^4-(B6-(2*D6))^4)/64))/10000 -> 27.704694 | K6: =(Input!C$9*(Input!C$7+I6)*D6^2)/(0.644*F6*((B6/2)*D6)^0.5) -> 276.9379 | L6: =((384*Input!$C$4*$J6*Input!$C$5)/(5*$F6*100000))^(1/4) -> 4.5294718 | M6: =((160*Input!$C$6*$J6)/(B6*$F6))^0.5 -> 6.8414999 | N6: =((384*Input!$C$4*$J6*Input!$C$5)/(($F6*100000)))^(1/4) -> 6.7731401 | O6: =((240*Input!$C$6*$J6)/($B6*$F6))^0.5 -> 8.379092 | P6: =((185*Input!$G$4*($J6/(2.54)^4)*(Input!$G$5))/($F6*0.00571))^(1/4)*25.4/1000 -> 5.6429302 | Q6: =(((16*Input!$G$6*($J6/(2.54)^4))/(($B6/25.4)*($F6*0.00571)))^0.5)*25.4/1000 -> 6.8416414 | R6: =((384*Input!$G$4*($J6/(2.54)^4)*(Input!$G$5))/($F6*0.00571))^(1/4)*25.4/1000 -> 6.7732101 | S6: =(((24*Input!$G$6*($J6/(2.54)^4))/(($B6/25.4)*($F6*0.00571)))^0.5)*25.4/1000 -> 8.3792653 | T6: =((Input!$G$4*($J6/(2.54)^4)*(Input!$G$5))/(17.1*$F6*0.06854))^(1/4)*0.3048 -> 4.8508401 | U6: =(((20*Input!$G$6*($J6/(2.54)^4))/(($B6/25.4)*($F6*0.00571)))^0.5)*25.4/1000 -> 7.6491877 | V6: =((384*Input!$C$4*$J6*Input!$C$5)/(3*$F6*100000))^(1/4) -> 5.1464735 | W6: =(((200*Input!$C$6*($J6))/($B6*($F6)))^0.5) -> 7.6490295 | X6: =MIN(L6:W6) -> 4.5294718 | Y6: 6.5 | Z6: 5.25 | AA6: 7.9 | AB6: =Z6/MIN(L6:W6) -> 1.1590756 | AC6: =Y6/X6 -> 1.4350459 | AD6: =Y6/MIN(N6:O6) -> 0.95967305
A7: 2.5 | B7: 73.02 | C7: Sch 40 | D7: 5.16 | E7: 50 | F7: =((3.1428*(B7^2-(B7-2*D7)^2)/4)*7.85/1000)*9.81 -> 84.745953 | G7: =(3.14*(B7+E7)*E7*Input!C$2/1000000)*9.81 -> 37.894343 | H7: =((3.14*(B7-2*D7)^2)/4*Input!C$3/1000000)*9.81 -> 30.274275 | I7: =(Input!C$8/1067)*'Bare+Vapour'!B7 -> 1.1291753 | J7: =((3.1428*(B7^4-(B7-(2*D7))^4)/64))/10000 -> 63.712089 | K7: =(Input!C$9*(Input!C$7+I7)*D7^2)/(0.644*F7*((B7/2)*D7)^0.5) -> 240.83249 | L7: =((384*Input!$C$4*$J7*Input!$C$5)/(5*$F7*100000))^(1/4) -> 4.9691488 | M7: =((160*Input!$C$6*$J7)/(B7*$F7))^0.5 -> 7.4839345 | N7: =((384*Input!$C$4*$J7*Input!$C$5)/(($F7*100000)))^(1/4) -> 7.4306107 | O7: =((240*Input!$C$6*$J7)/($B7*$F7))^0.5 -> 9.1659104 | P7: =((185*Input!$G$4*($J7/(2.54)^4)*(Input!$G$5))/($F7*0.00571))^(1/4)*25.4/1000 -> 6.1906909 | Q7: =(((16*Input!$G$6*($J7/(2.54)^4))/(($B7/25.4)*($F7*0.00571)))^0.5)*25.4/1000 -> 7.4840893 | R7: =((384*Input!$G$4*($J7/(2.54)^4)*(Input!$G$5))/($F7*0.00571))^(1/4)*25.4/1000 -> 7.4306875 | S7: =(((24*Input!$G$6*($J7/(2.54)^4))/(($B7/25.4)*($F7*0.00571)))^0.5)*25.4/1000 -> 9.1661 | T7: =((Input!$G$4*($J7/(2.54)^4)*(Input!$G$5))/(17.1*$F7*0.06854))^(1/4)*0.3048 -> 5.3217125 | U7: =(((20*Input!$G$6*($J7/(2.54)^4))/(($B7/25.4)*($F7*0.00571)))^0.5)*25.4/1000 -> 8.3674662 | V7: =((384*Input!$C$4*$J7*Input!$C$5)/(3*$F7*100000))^(1/4) -> 5.6460431 | W7: =(((200*Input!$C$6*($J7))/($B7*($F7)))^0.5) -> 8.3672931 | X7: =MIN(L7:W7) -> 4.9691488 | Y7: 7.5 | Z7: - | AA7: - | AB7: - | AC7: =Y7/X7 -> 1.5093128 | AD7: =Y7/MIN(N7:O7) -> 1.0093383
A8: 3 | B8: 88.9 | C8: Sch 40 | D8: 5.49 | E8: 100 | F8: =((3.1428*(B8^2-(B8-2*D8)^2)/4)*7.85/1000)*9.81 -> 110.82708 | G8: =(3.14*(B8+E8)*E8*Input!C$2/1000000)*9.81 -> 116.37525 | H8: =((3.14*(B8-2*D8)^2)/4*Input!C$3/1000000)*9.81 -> 46.755914 | I8: =(Input!C$8/1067)*'Bare+Vapour'!B8 -> 1.3747423 | J8: =((3.1428*(B8^4-(B8-(2*D8))^4)/64))/10000 -> 125.69872 | K8: =(Input!C$9*(Input!C$7+I8)*D8^2)/(0.644*F8*((B8/2)*D8)^0.5) -> 183.60963 | L8: =((384*Input!$C$4*$J8*Input!$C$5)/(5*$F8*100000))^(1/4) -> 5.5071579 | M8: =((160*Input!$C$6*$J8)/(B8*$F8))^0.5 -> 8.3308834 | N8: =((384*Input!$C$4*$J8*Input!$C$5)/(($F8*100000)))^(1/4) -> 8.2351219 | O8: =((240*Input!$C$6*$J8)/($B8*$F8))^0.5 -> 10.203207 | P8: =((185*Input!$G$4*($J8/(2.54)^4)*(Input!$G$5))/($F8*0.00571))^(1/4)*25.4/1000 -> 6.8609562 | Q8: =(((16*Input!$G$6*($J8/(2.54)^4))/(($B8/25.4)*($F8*0.00571)))^0.5)*25.4/1000 -> 8.3310558 | R8: =((384*Input!$G$4*($J8/(2.54)^4)*(Input!$G$5))/($F8*0.00571))^(1/4)*25.4/1000 -> 8.235207 | S8: =(((24*Input!$G$6*($J8/(2.54)^4))/(($B8/25.4)*($F8*0.00571)))^0.5)*25.4/1000 -> 10.203418 | T8: =((Input!$G$4*($J8/(2.54)^4)*(Input!$G$5))/(17.1*$F8*0.06854))^(1/4)*0.3048 -> 5.8978936 | U8: =(((20*Input!$G$6*($J8/(2.54)^4))/(($B8/25.4)*($F8*0.00571)))^0.5)*25.4/1000 -> 9.3144035 | V8: =((384*Input!$C$4*$J8*Input!$C$5)/(3*$F8*100000))^(1/4) -> 6.2573395 | W8: =(((200*Input!$C$6*($J8))/($B8*($F8)))^0.5) -> 9.3142108 | X8: =MIN(L8:W8) -> 5.5071579 | Y8: 8 | Z8: 6.4 | AA8: 9.5 | AB8: =Z8/MIN(L8:W8) -> 1.1621239 | AC8: =Y8/X8 -> 1.4526549 | AD8: =Y8/MIN(N8:O8) -> 0.97144889
A9: 4 | B9: 114.3 | C9: Sch 40 | D9: 6.02 | E9: 100 | F9: =((3.1428*(B9^2-(B9-2*D9)^2)/4)*7.85/1000)*9.81 -> 157.76118 | G9: =(3.14*(B9+E9)*E9*Input!C$2/1000000)*9.81 -> 132.02337 | H9: =((3.14*(B9-2*D9)^2)/4*Input!C$3/1000000)*9.81 -> 80.528617 | I9: =(Input!C$8/1067)*'Bare+Vapour'!B9 -> 1.7675258 | J9: =((3.1428*(B9^4-(B9-(2*D9))^4)/64))/10000 -> 301.16765 | K9: =(Input!C$9*(Input!C$7+I9)*D9^2)/(0.644*F9*((B9/2)*D9)^0.5) -> 131.12474 | L9: =((384*Input!$C$4*$J9*Input!$C$5)/(5*$F9*100000))^(1/4) -> 6.272755 | M9: =((160*Input!$C$6*$J9)/(B9*$F9))^0.5 -> 9.5319207 | N9: =((384*Input!$C$4*$J9*Input!$C$5)/(($F9*100000)))^(1/4) -> 9.3799566 | O9: =((240*Input!$C$6*$J9)/($B9*$F9))^0.5 -> 11.674171 | P9: =((185*Input!$G$4*($J9/(2.54)^4)*(Input!$G$5))/($F9*0.00571))^(1/4)*25.4/1000 -> 7.8147564 | Q9: =(((16*Input!$G$6*($J9/(2.54)^4))/(($B9/25.4)*($F9*0.00571)))^0.5)*25.4/1000 -> 9.5321178 | R9: =((384*Input!$G$4*($J9/(2.54)^4)*(Input!$G$5))/($F9*0.00571))^(1/4)*25.4/1000 -> 9.3800536 | S9: =(((24*Input!$G$6*($J9/(2.54)^4))/(($B9/25.4)*($F9*0.00571)))^0.5)*25.4/1000 -> 11.674412 | T9: =((Input!$G$4*($J9/(2.54)^4)*(Input!$G$5))/(17.1*$F9*0.06854))^(1/4)*0.3048 -> 6.7178103 | U9: =(((20*Input!$G$6*($J9/(2.54)^4))/(($B9/25.4)*($F9*0.00571)))^0.5)*25.4/1000 -> 10.657232 | V9: =((384*Input!$C$4*$J9*Input!$C$5)/(3*$F9*100000))^(1/4) -> 7.1272257 | W9: =(((200*Input!$C$6*($J9))/($B9*($F9)))^0.5) -> 10.657011 | X9: =MIN(L9:W9) -> 6.272755 | Y9: 9 | Z9: 7.3 | AB9: =Z9/MIN(L9:W9) -> 1.163763 | AC9: =Y9/X9 -> 1.4347763 | AD9: =Y9/MIN(N9:O9) -> 0.95949271
A10: 6 | B10: 168.27 | C10: Sch 40 | D10: 7.11 | E10: 100 | F10: =((3.1428*(B10^2-(B10-2*D10)^2)/4)*7.85/1000)*9.81 -> 277.32069 | G10: =(3.14*(B10+E10)*E10*Input!C$2/1000000)*9.81 -> 165.27256 | H10: =((3.14*(B10-2*D10)^2)/4*Input!C$3/1000000)*9.81 -> 182.75197 | I10: =(Input!C$8/1067)*'Bare+Vapour'!B10 -> 2.6021134 | J10: =((3.1428*(B10^4-(B10-(2*D10))^4)/64))/10000 -> 1171.4199 | K10: =(Input!C$9*(Input!C$7+I10)*D10^2)/(0.644*F10*((B10/2)*D10)^0.5) -> 79.557115 | L10: =((384*Input!$C$4*$J10*Input!$C$5)/(5*$F10*100000))^(1/4) -> 7.6504833 | M10: =((160*Input!$C$6*$J10)/(B10*$F10))^0.5 -> 11.685876 | N10: =((384*Input!$C$4*$J10*Input!$C$5)/(($F10*100000)))^(1/4) -> 11.440141 | O10: =((240*Input!$C$6*$J10)/($B10*$F10))^0.5 -> 14.312217 | P10: =((185*Input!$G$4*($J10/(2.54)^4)*(Input!$G$5))/($F10*0.00571))^(1/4)*25.4/1000 -> 9.531165 | Q10: =(((16*Input!$G$6*($J10/(2.54)^4))/(($B10/25.4)*($F10*0.00571)))^0.5)*25.4/1000 -> 11.686118 | R10: =((384*Input!$G$4*($J10/(2.54)^4)*(Input!$G$5))/($F10*0.00571))^(1/4)*25.4/1000 -> 11.440259 | S10: =(((24*Input!$G$6*($J10/(2.54)^4))/(($B10/25.4)*($F10*0.00571)))^0.5)*25.4/1000 -> 14.312513 | T10: =((Input!$G$4*($J10/(2.54)^4)*(Input!$G$5))/(17.1*$F10*0.06854))^(1/4)*0.3048 -> 8.1932891 | U10: =(((20*Input!$G$6*($J10/(2.54)^4))/(($B10/25.4)*($F10*0.00571)))^0.5)*25.4/1000 -> 13.065477 | V10: =((384*Input!$C$4*$J10*Input!$C$5)/(3*$F10*100000))^(1/4) -> 8.6926273 | W10: =(((200*Input!$C$6*($J10))/($B10*($F10)))^0.5) -> 13.065207 | X10: =MIN(L10:W10) -> 7.6504833 | Y10: 10.5 | Z10: 8.9 | AB10: =Z10/MIN(L10:W10) -> 1.1633252 | AC10: =Y10/X10 -> 1.3724623 | AD10: =Y10/MIN(N10:O10) -> 0.91782087
A11: 8 | B11: 219.07 | C11: Sch 40 | D11: 8.18 | E11: 120 | F11: =((3.1428*(B11^2-(B11-2*D11)^2)/4)*7.85/1000)*9.81 -> 417.5079 | G11: =(3.14*(B11+E11)*E11*Input!C$2/1000000)*9.81 -> 250.66821 | H11: =((3.14*(B11-2*D11)^2)/4*Input!C$3/1000000)*9.81 -> 316.43828 | I11: =(Input!C$8/1067)*'Bare+Vapour'!B11 -> 3.3876804 | J11: =((3.1428*(B11^4-(B11-(2*D11))^4)/64))/10000 -> 3018.5678 | K11: =(Input!C$9*(Input!C$7+I11)*D11^2)/(0.644*F11*((B11/2)*D11)^0.5) -> 57.589927 | L11: =((384*Input!$C$4*$J11*Input!$C$5)/(5*$F11*100000))^(1/4) -> 8.7506506 | M11: =((160*Input!$C$6*$J11)/(B11*$F11))^0.5 -> 13.399115 | N11: =((384*Input!$C$4*$J11*Input!$C$5)/(($F11*100000)))^(1/4) -> 13.085275 | O11: =((240*Input!$C$6*$J11)/($B11*$F11))^0.5 -> 16.410497 | P11: =((185*Input!$G$4*($J11/(2.54)^4)*(Input!$G$5))/($F11*0.00571))^(1/4)*25.4/1000 -> 10.901781 | Q11: =(((16*Input!$G$6*($J11/(2.54)^4))/(($B11/25.4)*($F11*0.00571)))^0.5)*25.4/1000 -> 13.399392 | R11: =((384*Input!$G$4*($J11/(2.54)^4)*(Input!$G$5))/($F11*0.00571))^(1/4)*25.4/1000 -> 13.08541 | S11: =(((24*Input!$G$6*($J11/(2.54)^4))/(($B11/25.4)*($F11*0.00571)))^0.5)*25.4/1000 -> 16.410837 | T11: =((Input!$G$4*($J11/(2.54)^4)*(Input!$G$5))/(17.1*$F11*0.06854))^(1/4)*0.3048 -> 9.3715138 | U11: =(((20*Input!$G$6*($J11/(2.54)^4))/(($B11/25.4)*($F11*0.00571)))^0.5)*25.4/1000 -> 14.980976 | V11: =((384*Input!$C$4*$J11*Input!$C$5)/(3*$F11*100000))^(1/4) -> 9.9426587 | W11: =(((200*Input!$C$6*($J11))/($B11*($F11)))^0.5) -> 14.980666 | X11: =MIN(L11:W11) -> 8.7506506 | Y11: 12 | Z11: 10.25 | AB11: =Z11/MIN(L11:W11) -> 1.1713415 | AC11: =Y11/X11 -> 1.3713266 | AD11: =Y11/MIN(N11:O11) -> 0.91706138
A12: 10 | B12: 273.05 | C12: Sch 40 | D12: 9.27 | E12: 120 | F12: =((3.1428*(B12^2-(B12-2*D12)^2)/4)*7.85/1000)*9.81 -> 591.80279 | G12: =(3.14*(B12+E12)*E12*Input!C$2/1000000)*9.81 -> 290.57463 | H12: =((3.14*(B12-2*D12)^2)/4*Input!C$3/1000000)*9.81 -> 498.82518 | I12: =(Input!C$8/1067)*'Bare+Vapour'!B12 -> 4.2224227 | J12: =((3.1428*(B12^4-(B12-(2*D12))^4)/64))/10000 -> 6692.1878 | K12: =(Input!C$9*(Input!C$7+I12)*D12^2)/(0.644*F12*((B12/2)*D12)^0.5) -> 44.257472 | L12: =((384*Input!$C$4*$J12*Input!$C$5)/(5*$F12*100000))^(1/4) -> 9.7859741 | M12: =((160*Input!$C$6*$J12)/(B12*$F12))^0.5 -> 15.009766 | N12: =((384*Input!$C$4*$J12*Input!$C$5)/(($F12*100000)))^(1/4) -> 14.633444 | O12: =((240*Input!$C$6*$J12)/($B12*$F12))^0.5 -> 18.383134 | P12: =((185*Input!$G$4*($J12/(2.54)^4)*(Input!$G$5))/($F12*0.00571))^(1/4)*25.4/1000 -> 12.191613 | Q12: =(((16*Input!$G$6*($J12/(2.54)^4))/(($B12/25.4)*($F12*0.00571)))^0.5)*25.4/1000 -> 15.010076 | R12: =((384*Input!$G$4*($J12/(2.54)^4)*(Input!$G$5))/($F12*0.00571))^(1/4)*25.4/1000 -> 14.633596 | S12: =(((24*Input!$G$6*($J12/(2.54)^4))/(($B12/25.4)*($F12*0.00571)))^0.5)*25.4/1000 -> 18.383514 | T12: =((Input!$G$4*($J12/(2.54)^4)*(Input!$G$5))/(17.1*$F12*0.06854))^(1/4)*0.3048 -> 10.480294 | U12: =(((20*Input!$G$6*($J12/(2.54)^4))/(($B12/25.4)*($F12*0.00571)))^0.5)*25.4/1000 -> 16.781775 | V12: =((384*Input!$C$4*$J12*Input!$C$5)/(3*$F12*100000))^(1/4) -> 11.119013 | W12: =(((200*Input!$C$6*($J12))/($B12*($F12)))^0.5) -> 16.781428 | X12: =MIN(L12:W12) -> 9.7859741 | Y12: 14 | Z12: 11.4 | AB12: =Z12/MIN(L12:W12) -> 1.1649326 | AC12: =Y12/X12 -> 1.430619 | AD12: =Y12/MIN(N12:O12) -> 0.95671255
A13: 12 | B13: 323.85 | C13: STD | D13: 9.53 | E13: 120 | F13: =((3.1428*(B13^2-(B13-2*D13)^2)/4)*7.85/1000)*9.81 -> 724.97048 | G13: =(3.14*(B13+E13)*E13*Input!C$2/1000000)*9.81 -> 328.13014 | H13: =((3.14*(B13-2*D13)^2)/4*Input!C$3/1000000)*9.81 -> 715.38543 | I13: =(Input!C$8/1067)*'Bare+Vapour'!B13 -> 5.0079897 | J13: =((3.1428*(B13^4-(B13-(2*D13))^4)/64))/10000 -> 11636.832 | K13: =(Input!C$9*(Input!C$7+I13)*D13^2)/(0.644*F13*((B13/2)*D13)^0.5) -> 34.839615 | L13: =((384*Input!$C$4*$J13*Input!$C$5)/(5*$F13*100000))^(1/4) -> 10.681565 | M13: =((160*Input!$C$6*$J13)/(B13*$F13))^0.5 -> 16.420437 | N13: =((384*Input!$C$4*$J13*Input!$C$5)/(($F13*100000)))^(1/4) -> 15.972665 | O13: =((240*Input!$C$6*$J13)/($B13*$F13))^0.5 -> 20.110846 | P13: =((185*Input!$G$4*($J13/(2.54)^4)*(Input!$G$5))/($F13*0.00571))^(1/4)*25.4/1000 -> 13.307363 | Q13: =(((16*Input!$G$6*($J13/(2.54)^4))/(($B13/25.4)*($F13*0.00571)))^0.5)*25.4/1000 -> 16.420777 | R13: =((384*Input!$G$4*($J13/(2.54)^4)*(Input!$G$5))/($F13*0.00571))^(1/4)*25.4/1000 -> 15.972831 | S13: =(((24*Input!$G$6*($J13/(2.54)^4))/(($B13/25.4)*($F13*0.00571)))^0.5)*25.4/1000 -> 20.111262 | T13: =((Input!$G$4*($J13/(2.54)^4)*(Input!$G$5))/(17.1*$F13*0.06854))^(1/4)*0.3048 -> 11.439428 | U13: =(((20*Input!$G$6*($J13/(2.54)^4))/(($B13/25.4)*($F13*0.00571)))^0.5)*25.4/1000 -> 18.358987 | V13: =((384*Input!$C$4*$J13*Input!$C$5)/(3*$F13*100000))^(1/4) -> 12.136601 | W13: =(((200*Input!$C$6*($J13))/($B13*($F13)))^0.5) -> 18.358607 | X13: =MIN(L13:W13) -> 10.681565 | Y13: 15 | Z13: 12.5 | AB13: =Z13/MIN(L13:W13) -> 1.1702405 | AC13: =Y13/X13 -> 1.4042886 | AD13: =Y13/MIN(N13:O13) -> 0.93910438
A14: 14 | B14: 355.6 | C14: STD | D14: 9.53 | E14: 120 | F14: =((3.1428*(B14^2-(B14-2*D14)^2)/4)*7.85/1000)*9.81 -> 798.20099 | G14: =(3.14*(B14+E14)*E14*Input!C$2/1000000)*9.81 -> 351.60233 | H14: =((3.14*(B14-2*D14)^2)/4*Input!C$3/1000000)*9.81 -> 872.19189 | I14: =(Input!C$8/1067)*'Bare+Vapour'!B14 -> 5.4989691 | J14: =((3.1428*(B14^4-(B14-(2*D14))^4)/64))/10000 -> 15528.901 | K14: =(Input!C$9*(Input!C$7+I14)*D14^2)/(0.644*F14*((B14/2)*D14)^0.5) -> 30.338797 | L14: =((384*Input!$C$4*$J14*Input!$C$5)/(5*$F14*100000))^(1/4) -> 11.20762 | M14: =((160*Input!$C$6*$J14)/(B14*$F14))^0.5 -> 17.251736 | N14: =((384*Input!$C$4*$J14*Input!$C$5)/(($F14*100000)))^(1/4) -> 16.759301 | O14: =((240*Input!$C$6*$J14)/($B14*$F14))^0.5 -> 21.128975 | P14: =((185*Input!$G$4*($J14/(2.54)^4)*(Input!$G$5))/($F14*0.00571))^(1/4)*25.4/1000 -> 13.962736 | Q14: =(((16*Input!$G$6*($J14/(2.54)^4))/(($B14/25.4)*($F14*0.00571)))^0.5)*25.4/1000 -> 17.252093 | R14: =((384*Input!$G$4*($J14/(2.54)^4)*(Input!$G$5))/($F14*0.00571))^(1/4)*25.4/1000 -> 16.759474 | S14: =(((24*Input!$G$6*($J14/(2.54)^4))/(($B14/25.4)*($F14*0.00571)))^0.5)*25.4/1000 -> 21.129412 | T14: =((Input!$G$4*($J14/(2.54)^4)*(Input!$G$5))/(17.1*$F14*0.06854))^(1/4)*0.3048 -> 12.002807 | U14: =(((20*Input!$G$6*($J14/(2.54)^4))/(($B14/25.4)*($F14*0.00571)))^0.5)*25.4/1000 -> 19.288426 | V14: =((384*Input!$C$4*$J14*Input!$C$5)/(3*$F14*100000))^(1/4) -> 12.734315 | W14: =(((200*Input!$C$6*($J14))/($B14*($F14)))^0.5) -> 19.288027 | X14: =MIN(L14:W14) -> 11.20762 | Y14: 16 | Z14: 13 | AB14: =Z14/MIN(L14:W14) -> 1.1599251 | AC14: =Y14/X14 -> 1.4276001 | AD14: =Y14/MIN(N14:O14) -> 0.95469375
A15: 16 | B15: 406.4 | C15: STD | D15: 9.53 | E15: 120 | F15: =((3.1428*(B15^2-(B15-2*D15)^2)/4)*7.85/1000)*9.81 -> 915.3698 | G15: =(3.14*(B15+E15)*E15*Input!C$2/1000000)*9.81 -> 389.15783 | H15: =((3.14*(B15-2*D15)^2)/4*Input!C$3/1000000)*9.81 -> 1155.376 | I15: =(Input!C$8/1067)*'Bare+Vapour'!B15 -> 6.2845361 | J15: =((3.1428*(B15^4-(B15-(2*D15))^4)/64))/10000 -> 23416.114 | K15: =(Input!C$9*(Input!C$7+I15)*D15^2)/(0.644*F15*((B15/2)*D15)^0.5) -> 24.931014 | L15: =((384*Input!$C$4*$J15*Input!$C$5)/(5*$F15*100000))^(1/4) -> 12.001509 | M15: =((160*Input!$C$6*$J15)/(B15*$F15))^0.5 -> 18.504686 | N15: =((384*Input!$C$4*$J15*Input!$C$5)/(($F15*100000)))^(1/4) -> 17.946441 | O15: =((240*Input!$C$6*$J15)/($B15*$F15))^0.5 -> 22.663519 | P15: =((185*Input!$G$4*($J15/(2.54)^4)*(Input!$G$5))/($F15*0.00571))^(1/4)*25.4/1000 -> 14.951782 | Q15: =(((16*Input!$G$6*($J15/(2.54)^4))/(($B15/25.4)*($F15*0.00571)))^0.5)*25.4/1000 -> 18.505069 | R15: =((384*Input!$G$4*($J15/(2.54)^4)*(Input!$G$5))/($F15*0.00571))^(1/4)*25.4/1000 -> 17.946627 | S15: =(((24*Input!$G$6*($J15/(2.54)^4))/(($B15/25.4)*($F15*0.00571)))^0.5)*25.4/1000 -> 22.663988 | T15: =((Input!$G$4*($J15/(2.54)^4)*(Input!$G$5))/(17.1*$F15*0.06854))^(1/4)*0.3048 -> 12.853022 | U15: =(((20*Input!$G$6*($J15/(2.54)^4))/(($B15/25.4)*($F15*0.00571)))^0.5)*25.4/1000 -> 20.689296 | V15: =((384*Input!$C$4*$J15*Input!$C$5)/(3*$F15*100000))^(1/4) -> 13.636347 | W15: =(((200*Input!$C$6*($J15))/($B15*($F15)))^0.5) -> 20.688868 | X15: =MIN(L15:W15) -> 12.001509 | Y15: 17 | Z15: 14 | AB15: =Z15/MIN(L15:W15) -> 1.16652 | AC15: =Y15/X15 -> 1.4164886 | AD15: =Y15/MIN(N15:O15) -> 0.947263
A16: 18 | B16: 457.2 | C16: STD | D16: 9.53 | E16: 120 | F16: =((3.1428*(B16^2-(B16-2*D16)^2)/4)*7.85/1000)*9.81 -> 1032.5386 | G16: =(3.14*(B16+E16)*E16*Input!C$2/1000000)*9.81 -> 426.71334 | H16: =((3.14*(B16-2*D16)^2)/4*Input!C$3/1000000)*9.81 -> 1478.3065 | I16: =(Input!C$8/1067)*'Bare+Vapour'!B16 -> 7.0701031 | J16: =((3.1428*(B16^4-(B16-(2*D16))^4)/64))/10000 -> 33603.956 | K16: =(Input!C$9*(Input!C$7+I16)*D16^2)/(0.644*F16*((B16/2)*D16)^0.5) -> 20.991917 | L16: =((384*Input!$C$4*$J16*Input!$C$5)/(5*$F16*100000))^(1/4) -> 12.7461 | M16: =((160*Input!$C$6*$J16)/(B16*$F16))^0.5 -> 19.678337 | N16: =((384*Input!$C$4*$J16*Input!$C$5)/(($F16*100000)))^(1/4) -> 19.059865 | O16: =((240*Input!$C$6*$J16)/($B16*$F16))^0.5 -> 24.100942 | P16: =((185*Input!$G$4*($J16/(2.54)^4)*(Input!$G$5))/($F16*0.00571))^(1/4)*25.4/1000 -> 15.879412 | Q16: =(((16*Input!$G$6*($J16/(2.54)^4))/(($B16/25.4)*($F16*0.00571)))^0.5)*25.4/1000 -> 19.678744 | R16: =((384*Input!$G$4*($J16/(2.54)^4)*(Input!$G$5))/($F16*0.00571))^(1/4)*25.4/1000 -> 19.060062 | S16: =(((24*Input!$G$6*($J16/(2.54)^4))/(($B16/25.4)*($F16*0.00571)))^0.5)*25.4/1000 -> 24.101441 | T16: =((Input!$G$4*($J16/(2.54)^4)*(Input!$G$5))/(17.1*$F16*0.06854))^(1/4)*0.3048 -> 13.650442 | U16: =(((20*Input!$G$6*($J16/(2.54)^4))/(($B16/25.4)*($F16*0.00571)))^0.5)*25.4/1000 -> 22.001504 | V16: =((384*Input!$C$4*$J16*Input!$C$5)/(3*$F16*100000))^(1/4) -> 14.482365 | W16: =(((200*Input!$C$6*($J16))/($B16*($F16)))^0.5) -> 22.001049 | X16: =MIN(L16:W16) -> 12.7461 | Y16: 18 | Z16: 14.9 | AB16: =Z16/MIN(L16:W16) -> 1.1689851 | AC16: =Y16/X16 -> 1.4121967 | AD16: =Y16/MIN(N16:O16) -> 0.94439286
A17: 20 | B17: 508 | C17: STD | D17: 9.53 | E17: 140 | F17: =((3.1428*(B17^2-(B17-2*D17)^2)/4)*7.85/1000)*9.81 -> 1149.7074 | G17: =(3.14*(B17+E17)*E17*Input!C$2/1000000)*9.81 -> 558.89689 | H17: =((3.14*(B17-2*D17)^2)/4*Input!C$3/1000000)*9.81 -> 1840.9831 | I17: =(Input!C$8/1067)*'Bare+Vapour'!B17 -> 7.8556701 | J17: =((3.1428*(B17^4-(B17-(2*D17))^4)/64))/10000 -> 46386.911 | K17: =(Input!C$9*(Input!C$7+I17)*D17^2)/(0.644*F17*((B17/2)*D17)^0.5) -> 18.016361 | L17: =((384*Input!$C$4*$J17*Input!$C$5)/(5*$F17*100000))^(1/4) -> 13.449567 | M17: =((160*Input!$C$6*$J17)/(B17*$F17))^0.5 -> 20.786035 | N17: =((384*Input!$C$4*$J17*Input!$C$5)/(($F17*100000)))^(1/4) -> 20.111794 | O17: =((240*Input!$C$6*$J17)/($B17*$F17))^0.5 -> 25.45759 | P17: =((185*Input!$G$4*($J17/(2.54)^4)*(Input!$G$5))/($F17*0.00571))^(1/4)*25.4/1000 -> 16.75581 | Q17: =(((16*Input!$G$6*($J17/(2.54)^4))/(($B17/25.4)*($F17*0.00571)))^0.5)*25.4/1000 -> 20.786465 | R17: =((384*Input!$G$4*($J17/(2.54)^4)*(Input!$G$5))/($F17*0.00571))^(1/4)*25.4/1000 -> 20.112002 | S17: =(((24*Input!$G$6*($J17/(2.54)^4))/(($B17/25.4)*($F17*0.00571)))^0.5)*25.4/1000 -> 25.458116 | T17: =((Input!$G$4*($J17/(2.54)^4)*(Input!$G$5))/(17.1*$F17*0.06854))^(1/4)*0.3048 -> 14.403821 | U17: =(((20*Input!$G$6*($J17/(2.54)^4))/(($B17/25.4)*($F17*0.00571)))^0.5)*25.4/1000 -> 23.239974 | V17: =((384*Input!$C$4*$J17*Input!$C$5)/(3*$F17*100000))^(1/4) -> 15.281659 | W17: =(((200*Input!$C$6*($J17))/($B17*($F17)))^0.5) -> 23.239493 | X17: =MIN(L17:W17) -> 13.449567 | Y17: 19 | Z17: 15.6 | AB17: =Z17/MIN(L17:W17) -> 1.1598886 | AC17: =Y17/X17 -> 1.4126849 | AD17: =Y17/MIN(N17:O17) -> 0.9447193
A18: 24 | B18: 609.6 | C18: STD | D18: 9.53 | E18: 140 | F18: =((3.1428*(B18^2-(B18-2*D18)^2)/4)*7.85/1000)*9.81 -> 1384.045 | G18: =(3.14*(B18+E18)*E18*Input!C$2/1000000)*9.81 -> 646.5264 | H18: =((3.14*(B18-2*D18)^2)/4*Input!C$3/1000000)*9.81 -> 2685.5751 | I18: =(Input!C$8/1067)*'Bare+Vapour'!B18 -> 9.4268041 | J18: =((3.1428*(B18^4-(B18-(2*D18))^4)/64))/10000 -> 80916.097 | K18: =(Input!C$9*(Input!C$7+I18)*D18^2)/(0.644*F18*((B18/2)*D18)^0.5) -> 13.860991 | L18: =((384*Input!$C$4*$J18*Input!$C$5)/(5*$F18*100000))^(1/4) -> 14.756299 | M18: =((160*Input!$C$6*$J18)/(B18*$F18))^0.5 -> 22.841221 | N18: =((384*Input!$C$4*$J18*Input!$C$5)/(($F18*100000)))^(1/4) -> 22.065814 | O18: =((240*Input!$C$6*$J18)/($B18*$F18))^0.5 -> 27.974669 | P18: =((185*Input!$G$4*($J18/(2.54)^4)*(Input!$G$5))/($F18*0.00571))^(1/4)*25.4/1000 -> 18.38377 | Q18: =(((16*Input!$G$6*($J18/(2.54)^4))/(($B18/25.4)*($F18*0.00571)))^0.5)*25.4/1000 -> 22.841694 | R18: =((384*Input!$G$4*($J18/(2.54)^4)*(Input!$G$5))/($F18*0.00571))^(1/4)*25.4/1000 -> 22.066043 | S18: =(((24*Input!$G$6*($J18/(2.54)^4))/(($B18/25.4)*($F18*0.00571)))^0.5)*25.4/1000 -> 27.975247 | T18: =((Input!$G$4*($J18/(2.54)^4)*(Input!$G$5))/(17.1*$F18*0.06854))^(1/4)*0.3048 -> 15.803267 | U18: =(((20*Input!$G$6*($J18/(2.54)^4))/(($B18/25.4)*($F18*0.00571)))^0.5)*25.4/1000 -> 25.53779 | V18: =((384*Input!$C$4*$J18*Input!$C$5)/(3*$F18*100000))^(1/4) -> 16.766393 | W18: =(((200*Input!$C$6*($J18))/($B18*($F18)))^0.5) -> 25.537262 | X18: =MIN(L18:W18) -> 14.756299 | Y18: 21 | Z18: 17.2 | AB18: =Z18/MIN(L18:W18) -> 1.1656039 | AC18: =Y18/X18 -> 1.423121 | AD18: =Y18/MIN(N18:O18) -> 0.95169839
A19: 0.75 | B19: 26.67 | C19: Sch 80 | D19: 3.91 | E19: 40 | F19: =((3.1428*(B19^2-(B19-2*D19)^2)/4)*7.85/1000)*9.81 -> 21.537953 | G19: =(3.14*(B19+E19)*E19*Input!C$2/1000000)*9.81 -> 16.429301 | H19: =((3.14*(B19-2*D19)^2)/4*Input!C$3/1000000)*9.81 -> 2.7362853 | I19: =(Input!C$8/1067)*'Bare+Vapour'!B19 -> 0.41242268 | J19: =((3.1428*(B19^4-(B19-(2*D19))^4)/64))/10000 -> 1.8644554 | K19: =(Input!C$9*(Input!C$7+I19)*D19^2)/(0.644*F19*((B19/2)*D19)^0.5) -> 1026.9294 | L19: =((384*Input!$C$4*$J19*Input!$C$5)/(5*$F19*100000))^(1/4) -> 2.8946308 | M19: =((160*Input!$C$6*$J19)/(B19*$F19))^0.5 -> 4.202055 | N19: =((384*Input!$C$4*$J19*Input!$C$5)/(($F19*100000)))^(1/4) -> 4.3284826 | O19: =((240*Input!$C$6*$J19)/($B19*$F19))^0.5 -> 5.1464453 | P19: =((185*Input!$G$4*($J19/(2.54)^4)*(Input!$G$5))/($F19*0.00571))^(1/4)*25.4/1000 -> 3.6062041 | Q19: =(((16*Input!$G$6*($J19/(2.54)^4))/(($B19/25.4)*($F19*0.00571)))^0.5)*25.4/1000 -> 4.2021419 | R19: =((384*Input!$G$4*($J19/(2.54)^4)*(Input!$G$5))/($F19*0.00571))^(1/4)*25.4/1000 -> 4.3285274 | S19: =(((24*Input!$G$6*($J19/(2.54)^4))/(($B19/25.4)*($F19*0.00571)))^0.5)*25.4/1000 -> 5.1465517 | T19: =((Input!$G$4*($J19/(2.54)^4)*(Input!$G$5))/(17.1*$F19*0.06854))^(1/4)*0.3048 -> 3.1000064 | U19: =(((20*Input!$G$6*($J19/(2.54)^4))/(($B19/25.4)*($F19*0.00571)))^0.5)*25.4/1000 -> 4.6981375 | V19: =((384*Input!$C$4*$J19*Input!$C$5)/(3*$F19*100000))^(1/4) -> 3.2889356 | W19: =(((200*Input!$C$6*($J19))/($B19*($F19)))^0.5) -> 4.6980403 | X19: =MIN(L19:W19) -> 2.8946308 | Y19: 4.5 | Z19: - | AA19: - | AB19: - | AC19: =Y19/X19 -> 1.5546024 | AD19: =Y19/MIN(N19:O19) -> 1.0396253
A20: 1 | B20: 33.4 | C20: Sch 80 | D20: 4.55 | E20: 40 | F20: =((3.1428*(B20^2-(B20-2*D20)^2)/4)*7.85/1000)*9.81 -> 31.769664 | G20: =(3.14*(B20+E20)*E20*Input!C$2/1000000)*9.81 -> 18.087756 | H20: =((3.14*(B20-2*D20)^2)/4*Input!C$3/1000000)*9.81 -> 4.5472749 | I20: =(Input!C$8/1067)*'Bare+Vapour'!B20 -> 0.51649485 | J20: =((3.1428*(B20^4-(B20-(2*D20))^4)/64))/10000 -> 4.3989166 | K20: =(Input!C$9*(Input!C$7+I20)*D20^2)/(0.644*F20*((B20/2)*D20)^0.5) -> 781.75831 | L20: =((384*Input!$C$4*$J20*Input!$C$5)/(5*$F20*100000))^(1/4) -> 3.2552891 | M20: =((160*Input!$C$6*$J20)/(B20*$F20))^0.5 -> 4.7488972 | N20: =((384*Input!$C$4*$J20*Input!$C$5)/(($F20*100000)))^(1/4) -> 4.8677926 | O20: =((240*Input!$C$6*$J20)/($B20*$F20))^0.5 -> 5.8161875 | P20: =((185*Input!$G$4*($J20/(2.54)^4)*(Input!$G$5))/($F20*0.00571))^(1/4)*25.4/1000 -> 4.0555212 | Q20: =(((16*Input!$G$6*($J20/(2.54)^4))/(($B20/25.4)*($F20*0.00571)))^0.5)*25.4/1000 -> 4.7489955 | R20: =((384*Input!$G$4*($J20/(2.54)^4)*(Input!$G$5))/($F20*0.00571))^(1/4)*25.4/1000 -> 4.8678429 | S20: =(((24*Input!$G$6*($J20/(2.54)^4))/(($B20/25.4)*($F20*0.00571)))^0.5)*25.4/1000 -> 5.8163078 | T20: =((Input!$G$4*($J20/(2.54)^4)*(Input!$G$5))/(17.1*$F20*0.06854))^(1/4)*0.3048 -> 3.4862535 | U20: =(((20*Input!$G$6*($J20/(2.54)^4))/(($B20/25.4)*($F20*0.00571)))^0.5)*25.4/1000 -> 5.3095383 | V20: =((384*Input!$C$4*$J20*Input!$C$5)/(3*$F20*100000))^(1/4) -> 3.6987225 | W20: =(((200*Input!$C$6*($J20))/($B20*($F20)))^0.5) -> 5.3094285 | X20: =MIN(L20:W20) -> 3.2552891 | Y20: 5 | Z20: 3.8 | AA20: 5.7 | AB20: =Z20/MIN(L20:W20) -> 1.167331 | AC20: =Y20/X20 -> 1.5359619 | AD20: =Y20/MIN(N20:O20) -> 1.0271596
A21: 1.5 | B21: 48.26 | C21: Sch 80 | D21: 5.08 | E21: 50 | F21: =((3.1428*(B21^2-(B21-2*D21)^2)/4)*7.85/1000)*9.81 -> 53.088659 | G21: =(3.14*(B21+E21)*E21*Input!C$2/1000000)*9.81 -> 30.267421 | H21: =((3.14*(B21-2*D21)^2)/4*Input!C$3/1000000)*9.81 -> 11.178631 | I21: =(Input!C$8/1067)*'Bare+Vapour'!B21 -> 0.74628866 | J21: =((3.1428*(B21^4-(B21-(2*D21))^4)/64))/10000 -> 16.289515 | K21: =(Input!C$9*(Input!C$7+I21)*D21^2)/(0.644*F21*((B21/2)*D21)^0.5) -> 460.18572 | L21: =((384*Input!$C$4*$J21*Input!$C$5)/(5*$F21*100000))^(1/4) -> 3.971759 | M21: =((160*Input!$C$6*$J21)/(B21*$F21))^0.5 -> 5.8811058 | N21: =((384*Input!$C$4*$J21*Input!$C$5)/(($F21*100000)))^(1/4) -> 5.9391649 | O21: =((240*Input!$C$6*$J21)/($B21*$F21))^0.5 -> 7.2028542 | P21: =((185*Input!$G$4*($J21/(2.54)^4)*(Input!$G$5))/($F21*0.00571))^(1/4)*25.4/1000 -> 4.9481175 | Q21: =(((16*Input!$G$6*($J21/(2.54)^4))/(($B21/25.4)*($F21*0.00571)))^0.5)*25.4/1000 -> 5.8812274 | R21: =((384*Input!$G$4*($J21/(2.54)^4)*(Input!$G$5))/($F21*0.00571))^(1/4)*25.4/1000 -> 5.9392264 | S21: =(((24*Input!$G$6*($J21/(2.54)^4))/(($B21/25.4)*($F21*0.00571)))^0.5)*25.4/1000 -> 7.2030032 | T21: =((Input!$G$4*($J21/(2.54)^4)*(Input!$G$5))/(17.1*$F21*0.06854))^(1/4)*0.3048 -> 4.2535573 | U21: =(((20*Input!$G$6*($J21/(2.54)^4))/(($B21/25.4)*($F21*0.00571)))^0.5)*25.4/1000 -> 6.5754122 | V21: =((384*Input!$C$4*$J21*Input!$C$5)/(3*$F21*100000))^(1/4) -> 4.5127895 | W21: =(((200*Input!$C$6*($J21))/($B21*($F21)))^0.5) -> 6.5752762 | X21: =MIN(L21:W21) -> 3.971759 | Y21: 6 | Z21: 4.65 | AA21: 6.9 | AB21: =Z21/MIN(L21:W21) -> 1.1707659 | AC21: =Y21/X21 -> 1.5106657 | AD21: =Y21/MIN(N21:O21) -> 1.010243
A22: 2 | B22: 60.32 | C22: Sch 80 | D22: 5.54 | E22: 50 | F22: =((3.1428*(B22^2-(B22-2*D22)^2)/4)*7.85/1000)*9.81 -> 73.449222 | G22: =(3.14*(B22+E22)*E22*Input!C$2/1000000)*9.81 -> 33.982311 | H22: =((3.14*(B22-2*D22)^2)/4*Input!C$3/1000000)*9.81 -> 18.671308 | I22: =(Input!C$8/1067)*'Bare+Vapour'!B22 -> 0.93278351 | J22: =((3.1428*(B22^4-(B22-(2*D22))^4)/64))/10000 -> 36.142805 | K22: =(Input!C$9*(Input!C$7+I22)*D22^2)/(0.644*F22*((B22/2)*D22)^0.5) -> 339.45559 | L22: =((384*Input!$C$4*$J22*Input!$C$5)/(5*$F22*100000))^(1/4) -> 4.4695618 | M22: =((160*Input!$C$6*$J22)/(B22*$F22))^0.5 -> 6.6617159 | N22: =((384*Input!$C$4*$J22*Input!$C$5)/(($F22*100000)))^(1/4) -> 6.6835538 | O22: =((240*Input!$C$6*$J22)/($B22*$F22))^0.5 -> 8.1589024 | P22: =((185*Input!$G$4*($J22/(2.54)^4)*(Input!$G$5))/($F22*0.00571))^(1/4)*25.4/1000 -> 5.5682928 | Q22: =(((16*Input!$G$6*($J22/(2.54)^4))/(($B22/25.4)*($F22*0.00571)))^0.5)*25.4/1000 -> 6.6618537 | R22: =((384*Input!$G$4*($J22/(2.54)^4)*(Input!$G$5))/($F22*0.00571))^(1/4)*25.4/1000 -> 6.6836229 | S22: =(((24*Input!$G$6*($J22/(2.54)^4))/(($B22/25.4)*($F22*0.00571)))^0.5)*25.4/1000 -> 8.1590712 | T22: =((Input!$G$4*($J22/(2.54)^4)*(Input!$G$5))/(17.1*$F22*0.06854))^(1/4)*0.3048 -> 4.7866796 | U22: =(((20*Input!$G$6*($J22/(2.54)^4))/(($B22/25.4)*($F22*0.00571)))^0.5)*25.4/1000 -> 7.4481789 | V22: =((384*Input!$C$4*$J22*Input!$C$5)/(3*$F22*100000))^(1/4) -> 5.0784027 | W22: =(((200*Input!$C$6*($J22))/($B22*($F22)))^0.5) -> 7.4480248 | X22: =MIN(L22:W22) -> 4.4695618 | Y22: 6.5 | Z22: 5.25 | AA22: 7.9 | AB22: =Z22/MIN(L22:W22) -> 1.1746118 | AC22: =Y22/X22 -> 1.4542813 | AD22: =Y22/MIN(N22:O22) -> 0.9725365
A23: 2.5 | B23: 73.02 | C23: Sch 80 | D23: 7.01 | E23: 50 | F23: =((3.1428*(B23^2-(B23-2*D23)^2)/4)*7.85/1000)*9.81 -> 111.99101 | G23: =(3.14*(B23+E23)*E23*Input!C$2/1000000)*9.81 -> 37.894343 | H23: =((3.14*(B23-2*D23)^2)/4*Input!C$3/1000000)*9.81 -> 26.806659 | I23: =(Input!C$8/1067)*'Bare+Vapour'!B23 -> 1.1291753 | J23: =((3.1428*(B23^4-(B23-(2*D23))^4)/64))/10000 -> 80.102184 | K23: =(Input!C$9*(Input!C$7+I23)*D23^2)/(0.644*F23*((B23/2)*D23)^0.5) -> 288.57144 | L23: =((384*Input!$C$4*$J23*Input!$C$5)/(5*$F23*100000))^(1/4) -> 4.9076274 | M23: =((160*Input!$C$6*$J23)/(B23*$F23))^0.5 -> 7.2997693 | N23: =((384*Input!$C$4*$J23*Input!$C$5)/(($F23*100000)))^(1/4) -> 7.3386147 | O23: =((240*Input!$C$6*$J23)/($B23*$F23))^0.5 -> 8.940355 | P23: =((185*Input!$G$4*($J23/(2.54)^4)*(Input!$G$5))/($F23*0.00571))^(1/4)*25.4/1000 -> 6.114046 | Q23: =(((16*Input!$G$6*($J23/(2.54)^4))/(($B23/25.4)*($F23*0.00571)))^0.5)*25.4/1000 -> 7.2999203 | R23: =((384*Input!$G$4*($J23/(2.54)^4)*(Input!$G$5))/($F23*0.00571))^(1/4)*25.4/1000 -> 7.3386906 | S23: =(((24*Input!$G$6*($J23/(2.54)^4))/(($B23/25.4)*($F23*0.00571)))^0.5)*25.4/1000 -> 8.94054 | T23: =((Input!$G$4*($J23/(2.54)^4)*(Input!$G$5))/(17.1*$F23*0.06854))^(1/4)*0.3048 -> 5.2558262 | U23: =(((20*Input!$G$6*($J23/(2.54)^4))/(($B23/25.4)*($F23*0.00571)))^0.5)*25.4/1000 -> 8.161559 | V23: =((384*Input!$C$4*$J23*Input!$C$5)/(3*$F23*100000))^(1/4) -> 5.5761413 | W23: =(((200*Input!$C$6*($J23))/($B23*($F23)))^0.5) -> 8.1613902 | X23: =MIN(L23:W23) -> 4.9076274 | Y23: 7.5 | Z23: - | AA23: - | AB23: - | AC23: =Y23/X23 -> 1.5282334 | AD23: =Y23/MIN(N23:O23) -> 1.0219913
A24: 3 | B24: 88.9 | C24: Sch 80 | D24: 7.62 | E24: 100 | F24: =((3.1428*(B24^2-(B24-2*D24)^2)/4)*7.85/1000)*9.81 -> 149.89739 | G24: =(3.14*(B24+E24)*E24*Input!C$2/1000000)*9.81 -> 116.37525 | H24: =((3.14*(B24-2*D24)^2)/4*Input!C$3/1000000)*9.81 -> 41.783238 | I24: =(Input!C$8/1067)*'Bare+Vapour'!B24 -> 1.3747423 | J24: =((3.1428*(B24^4-(B24-(2*D24))^4)/64))/10000 -> 162.15606 | K24: =(Input!C$9*(Input!C$7+I24)*D24^2)/(0.644*F24*((B24/2)*D24)^0.5) -> 221.98376 | L24: =((384*Input!$C$4*$J24*Input!$C$5)/(5*$F24*100000))^(1/4) -> 5.4424076 | M24: =((160*Input!$C$6*$J24)/(B24*$F24))^0.5 -> 8.1361345 | N24: =((384*Input!$C$4*$J24*Input!$C$5)/(($F24*100000)))^(1/4) -> 8.1382975 | O24: =((240*Input!$C$6*$J24)/($B24*$F24))^0.5 -> 9.964689 | P24: =((185*Input!$G$4*($J24/(2.54)^4)*(Input!$G$5))/($F24*0.00571))^(1/4)*25.4/1000 -> 6.7802886 | Q24: =(((16*Input!$G$6*($J24/(2.54)^4))/(($B24/25.4)*($F24*0.00571)))^0.5)*25.4/1000 -> 8.1363028 | R24: =((384*Input!$G$4*($J24/(2.54)^4)*(Input!$G$5))/($F24*0.00571))^(1/4)*25.4/1000 -> 8.1383817 | S24: =(((24*Input!$G$6*($J24/(2.54)^4))/(($B24/25.4)*($F24*0.00571)))^0.5)*25.4/1000 -> 9.9648952 | T24: =((Input!$G$4*($J24/(2.54)^4)*(Input!$G$5))/(17.1*$F24*0.06854))^(1/4)*0.3048 -> 5.8285492 | U24: =(((20*Input!$G$6*($J24/(2.54)^4))/(($B24/25.4)*($F24*0.00571)))^0.5)*25.4/1000 -> 9.0966631 | V24: =((384*Input!$C$4*$J24*Input!$C$5)/(3*$F24*100000))^(1/4) -> 6.1837689 | W24: =(((200*Input!$C$6*($J24))/($B24*($F24)))^0.5) -> 9.0964749 | X24: =MIN(L24:W24) -> 5.4424076 | Y24: 8 | Z24: 6.4 | AA24: 9.5 | AB24: =Z24/MIN(L24:W24) -> 1.1759502 | AC24: =Y24/X24 -> 1.4699377 | AD24: =Y24/MIN(N24:O24) -> 0.98300658
A25: 4 | B25: 114.3 | C25: Sch 80 | D25: 8.56 | E25: 100 | F25: =((3.1428*(B25^2-(B25-2*D25)^2)/4)*7.85/1000)*9.81 -> 219.06272 | G25: =(3.14*(B25+E25)*E25*Input!C$2/1000000)*9.81 -> 132.02337 | H25: =((3.14*(B25-2*D25)^2)/4*Input!C$3/1000000)*9.81 -> 72.726461 | I25: =(Input!C$8/1067)*'Bare+Vapour'!B25 -> 1.7675258 | J25: =((3.1428*(B25^4-(B25-(2*D25))^4)/64))/10000 -> 400.1799 | K25: =(Input!C$9*(Input!C$7+I25)*D25^2)/(0.644*F25*((B25/2)*D25)^0.5) -> 160.11507 | L25: =((384*Input!$C$4*$J25*Input!$C$5)/(5*$F25*100000))^(1/4) -> 6.2040885 | M25: =((160*Input!$C$6*$J25)/(B25*$F25))^0.5 -> 9.324375 | N25: =((384*Input!$C$4*$J25*Input!$C$5)/(($F25*100000)))^(1/4) -> 9.2772762 | O25: =((240*Input!$C$6*$J25)/($B25*$F25))^0.5 -> 11.41998 | P25: =((185*Input!$G$4*($J25/(2.54)^4)*(Input!$G$5))/($F25*0.00571))^(1/4)*25.4/1000 -> 7.7292099 | Q25: =(((16*Input!$G$6*($J25/(2.54)^4))/(($B25/25.4)*($F25*0.00571)))^0.5)*25.4/1000 -> 9.3245679 | R25: =((384*Input!$G$4*($J25/(2.54)^4)*(Input!$G$5))/($F25*0.00571))^(1/4)*25.4/1000 -> 9.2773721 | S25: =(((24*Input!$G$6*($J25/(2.54)^4))/(($B25/25.4)*($F25*0.00571)))^0.5)*25.4/1000 -> 11.420217 | T25: =((Input!$G$4*($J25/(2.54)^4)*(Input!$G$5))/(17.1*$F25*0.06854))^(1/4)*0.3048 -> 6.6442718 | U25: =(((20*Input!$G$6*($J25/(2.54)^4))/(($B25/25.4)*($F25*0.00571)))^0.5)*25.4/1000 -> 10.425184 | V25: =((384*Input!$C$4*$J25*Input!$C$5)/(3*$F25*100000))^(1/4) -> 7.0492055 | W25: =(((200*Input!$C$6*($J25))/($B25*($F25)))^0.5) -> 10.424968 | X25: =MIN(L25:W25) -> 6.2040885 | Y25: 9 | Z25: 7.3 | AB25: =Z25/MIN(L25:W25) -> 1.1766434 | AC25: =Y25/X25 -> 1.4506563 | AD25: =Y25/MIN(N25:O25) -> 0.97011233
A26: 6 | B26: 168.27 | C26: Sch 80 | D26: 10.97 | E26: 100 | F26: =((3.1428*(B26^2-(B26-2*D26)^2)/4)*7.85/1000)*9.81 -> 417.62911 | G26: =(3.14*(B26+E26)*E26*Input!C$2/1000000)*9.81 -> 165.27256 | H26: =((3.14*(B26-2*D26)^2)/4*Input!C$3/1000000)*9.81 -> 164.89421 | I26: =(Input!C$8/1067)*'Bare+Vapour'!B26 -> 2.6021134 | J26: =((3.1428*(B26^4-(B26-(2*D26))^4)/64))/10000 -> 1685.4919 | K26: =(Input!C$9*(Input!C$7+I26)*D26^2)/(0.644*F26*((B26/2)*D26)^0.5) -> 101.24558 | L26: =((384*Input!$C$4*$J26*Input!$C$5)/(5*$F26*100000))^(1/4) -> 7.5638039 | M26: =((160*Input!$C$6*$J26)/(B26*$F26))^0.5 -> 11.422576 | N26: =((384*Input!$C$4*$J26*Input!$C$5)/(($F26*100000)))^(1/4) -> 11.310525 | O26: =((240*Input!$C$6*$J26)/($B26*$F26))^0.5 -> 13.989741 | P26: =((185*Input!$G$4*($J26/(2.54)^4)*(Input!$G$5))/($F26*0.00571))^(1/4)*25.4/1000 -> 9.4231776 | Q26: =(((16*Input!$G$6*($J26/(2.54)^4))/(($B26/25.4)*($F26*0.00571)))^0.5)*25.4/1000 -> 11.422812 | R26: =((384*Input!$G$4*($J26/(2.54)^4)*(Input!$G$5))/($F26*0.00571))^(1/4)*25.4/1000 -> 11.310642 | S26: =(((24*Input!$G$6*($J26/(2.54)^4))/(($B26/25.4)*($F26*0.00571)))^0.5)*25.4/1000 -> 13.990031 | T26: =((Input!$G$4*($J26/(2.54)^4)*(Input!$G$5))/(17.1*$F26*0.06854))^(1/4)*0.3048 -> 8.1004597 | U26: =(((20*Input!$G$6*($J26/(2.54)^4))/(($B26/25.4)*($F26*0.00571)))^0.5)*25.4/1000 -> 12.771092 | V26: =((384*Input!$C$4*$J26*Input!$C$5)/(3*$F26*100000))^(1/4) -> 8.5941404 | W26: =(((200*Input!$C$6*($J26))/($B26*($F26)))^0.5) -> 12.770828 | X26: =MIN(L26:W26) -> 7.5638039 | Y26: 10.5 | Z26: 8.9 | AB26: =Z26/MIN(L26:W26) -> 1.1766566 | AC26: =Y26/X26 -> 1.3881904 | AD26: =Y26/MIN(N26:O26) -> 0.92833888
A27: 8 | B27: 219.07 | C27: XS | D27: 12.7 | E27: 120 | F27: =((3.1428*(B27^2-(B27-2*D27)^2)/4)*7.85/1000)*9.81 -> 634.31604 | G27: =(3.14*(B27+E27)*E27*Input!C$2/1000000)*9.81 -> 250.66821 | H27: =((3.14*(B27-2*D27)^2)/4*Input!C$3/1000000)*9.81 -> 288.84401 | I27: =(Input!C$8/1067)*'Bare+Vapour'!B27 -> 3.3876804 | J27: =((3.1428*(B27^4-(B27-(2*D27))^4)/64))/10000 -> 4401.6125 | K27: =(Input!C$9*(Input!C$7+I27)*D27^2)/(0.644*F27*((B27/2)*D27)^0.5) -> 73.329911 | L27: =((384*Input!$C$4*$J27*Input!$C$5)/(5*$F27*100000))^(1/4) -> 8.6612947 | M27: =((160*Input!$C$6*$J27)/(B27*$F27))^0.5 -> 13.126866 | N27: =((384*Input!$C$4*$J27*Input!$C$5)/(($F27*100000)))^(1/4) -> 12.951656 | O27: =((240*Input!$C$6*$J27)/($B27*$F27))^0.5 -> 16.077062 | P27: =((185*Input!$G$4*($J27/(2.54)^4)*(Input!$G$5))/($F27*0.00571))^(1/4)*25.4/1000 -> 10.790459 | Q27: =(((16*Input!$G$6*($J27/(2.54)^4))/(($B27/25.4)*($F27*0.00571)))^0.5)*25.4/1000 -> 13.127138 | R27: =((384*Input!$G$4*($J27/(2.54)^4)*(Input!$G$5))/($F27*0.00571))^(1/4)*25.4/1000 -> 12.95179 | S27: =(((24*Input!$G$6*($J27/(2.54)^4))/(($B27/25.4)*($F27*0.00571)))^0.5)*25.4/1000 -> 16.077394 | T27: =((Input!$G$4*($J27/(2.54)^4)*(Input!$G$5))/(17.1*$F27*0.06854))^(1/4)*0.3048 -> 9.275818 | U27: =(((20*Input!$G$6*($J27/(2.54)^4))/(($B27/25.4)*($F27*0.00571)))^0.5)*25.4/1000 -> 14.676586 | V27: =((384*Input!$C$4*$J27*Input!$C$5)/(3*$F27*100000))^(1/4) -> 9.8411307 | W27: =(((200*Input!$C$6*($J27))/($B27*($F27)))^0.5) -> 14.676282 | X27: =MIN(L27:W27) -> 8.6612947 | Y27: 12 | Z27: 10.25 | AB27: =Z27/MIN(L27:W27) -> 1.1834259 | AC27: =Y27/X27 -> 1.3854742 | AD27: =Y27/MIN(N27:O27) -> 0.92652242
A28: 10 | B28: 273.05 | C28: XS | D28: 12.7 | E28: 120 | F28: =((3.1428*(B28^2-(B28-2*D28)^2)/4)*7.85/1000)*9.81 -> 800.23347 | G28: =(3.14*(B28+E28)*E28*Input!C$2/1000000)*9.81 -> 290.57463 | H28: =((3.14*(B28-2*D28)^2)/4*Input!C$3/1000000)*9.81 -> 472.29715 | I28: =(Input!C$8/1067)*'Bare+Vapour'!B28 -> 4.2224227 | J28: =((3.1428*(B28^4-(B28-(2*D28))^4)/64))/10000 -> 8825.4207 | K28: =(Input!C$9*(Input!C$7+I28)*D28^2)/(0.644*F28*((B28/2)*D28)^0.5) -> 52.484719 | L28: =((384*Input!$C$4*$J28*Input!$C$5)/(5*$F28*100000))^(1/4) -> 9.7249183 | M28: =((160*Input!$C$6*$J28)/(B28*$F28))^0.5 -> 14.823055 | N28: =((384*Input!$C$4*$J28*Input!$C$5)/(($F28*100000)))^(1/4) -> 14.542145 | O28: =((240*Input!$C$6*$J28)/($B28*$F28))^0.5 -> 18.15446 | P28: =((185*Input!$G$4*($J28/(2.54)^4)*(Input!$G$5))/($F28*0.00571))^(1/4)*25.4/1000 -> 12.115548 | Q28: =(((16*Input!$G$6*($J28/(2.54)^4))/(($B28/25.4)*($F28*0.00571)))^0.5)*25.4/1000 -> 14.823361 | R28: =((384*Input!$G$4*($J28/(2.54)^4)*(Input!$G$5))/($F28*0.00571))^(1/4)*25.4/1000 -> 14.542295 | S28: =(((24*Input!$G$6*($J28/(2.54)^4))/(($B28/25.4)*($F28*0.00571)))^0.5)*25.4/1000 -> 18.154836 | T28: =((Input!$G$4*($J28/(2.54)^4)*(Input!$G$5))/(17.1*$F28*0.06854))^(1/4)*0.3048 -> 10.414906 | U28: =(((20*Input!$G$6*($J28/(2.54)^4))/(($B28/25.4)*($F28*0.00571)))^0.5)*25.4/1000 -> 16.573022 | V28: =((384*Input!$C$4*$J28*Input!$C$5)/(3*$F28*100000))^(1/4) -> 11.04964 | W28: =(((200*Input!$C$6*($J28))/($B28*($F28)))^0.5) -> 16.572679 | X28: =MIN(L28:W28) -> 9.7249183 | Y28: 14 | Z28: 11.4 | AB28: =Z28/MIN(L28:W28) -> 1.1722464 | AC28: =Y28/X28 -> 1.4396008 | AD28: =Y28/MIN(N28:O28) -> 0.96271907
A29: 12 | B29: 323.85 | C29: XS | D29: 12.7 | E29: 120 | F29: =((3.1428*(B29^2-(B29-2*D29)^2)/4)*7.85/1000)*9.81 -> 956.37659 | G29: =(3.14*(B29+E29)*E29*Input!C$2/1000000)*9.81 -> 328.13014 | H29: =((3.14*(B29-2*D29)^2)/4*Input!C$3/1000000)*9.81 -> 685.93321 | I29: =(Input!C$8/1067)*'Bare+Vapour'!B29 -> 5.0079897 | J29: =((3.1428*(B29^4-(B29-(2*D29))^4)/64))/10000 -> 15054.378 | K29: =(Input!C$9*(Input!C$7+I29)*D29^2)/(0.644*F29*((B29/2)*D29)^0.5) -> 40.628517 | L29: =((384*Input!$C$4*$J29*Input!$C$5)/(5*$F29*100000))^(1/4) -> 10.629547 | M29: =((160*Input!$C$6*$J29)/(B29*$F29))^0.5 -> 16.260895 | N29: =((384*Input!$C$4*$J29*Input!$C$5)/(($F29*100000)))^(1/4) -> 15.89488 | O29: =((240*Input!$C$6*$J29)/($B29*$F29))^0.5 -> 19.915447 | P29: =((185*Input!$G$4*($J29/(2.54)^4)*(Input!$G$5))/($F29*0.00571))^(1/4)*25.4/1000 -> 13.242558 | Q29: =(((16*Input!$G$6*($J29/(2.54)^4))/(($B29/25.4)*($F29*0.00571)))^0.5)*25.4/1000 -> 16.261231 | R29: =((384*Input!$G$4*($J29/(2.54)^4)*(Input!$G$5))/($F29*0.00571))^(1/4)*25.4/1000 -> 15.895044 | S29: =(((24*Input!$G$6*($J29/(2.54)^4))/(($B29/25.4)*($F29*0.00571)))^0.5)*25.4/1000 -> 19.915859 | T29: =((Input!$G$4*($J29/(2.54)^4)*(Input!$G$5))/(17.1*$F29*0.06854))^(1/4)*0.3048 -> 11.383719 | U29: =(((20*Input!$G$6*($J29/(2.54)^4))/(($B29/25.4)*($F29*0.00571)))^0.5)*25.4/1000 -> 18.180609 | V29: =((384*Input!$C$4*$J29*Input!$C$5)/(3*$F29*100000))^(1/4) -> 12.077497 | W29: =(((200*Input!$C$6*($J29))/($B29*($F29)))^0.5) -> 18.180233 | X29: =MIN(L29:W29) -> 10.629547 | Y29: 15 | Z29: 12.5 | AB29: =Z29/MIN(L29:W29) -> 1.1759673 | AC29: =Y29/X29 -> 1.4111608 | AD29: =Y29/MIN(N29:O29) -> 0.94370011
A30: 14 | B30: 355.6 | C30: XS | D30: 12.7 | E30: 120 | F30: =((3.1428*(B30^2-(B30-2*D30)^2)/4)*7.85/1000)*9.81 -> 1053.966 | G30: =(3.14*(B30+E30)*E30*Input!C$2/1000000)*9.81 -> 351.60233 | H30: =((3.14*(B30-2*D30)^2)/4*Input!C$3/1000000)*9.81 -> 839.63939 | I30: =(Input!C$8/1067)*'Bare+Vapour'!B30 -> 5.4989691 | J30: =((3.1428*(B30^4-(B30-(2*D30))^4)/64))/10000 -> 20143.191 | K30: =(Input!C$9*(Input!C$7+I30)*D30^2)/(0.644*F30*((B30/2)*D30)^0.5) -> 35.346811 | L30: =((384*Input!$C$4*$J30*Input!$C$5)/(5*$F30*100000))^(1/4) -> 11.15788 | M30: =((160*Input!$C$6*$J30)/(B30*$F30))^0.5 -> 17.098948 | N30: =((384*Input!$C$4*$J30*Input!$C$5)/(($F30*100000)))^(1/4) -> 16.684923 | O30: =((240*Input!$C$6*$J30)/($B30*$F30))^0.5 -> 20.941849 | P30: =((185*Input!$G$4*($J30/(2.54)^4)*(Input!$G$5))/($F30*0.00571))^(1/4)*25.4/1000 -> 13.900769 | Q30: =(((16*Input!$G$6*($J30/(2.54)^4))/(($B30/25.4)*($F30*0.00571)))^0.5)*25.4/1000 -> 17.099302 | R30: =((384*Input!$G$4*($J30/(2.54)^4)*(Input!$G$5))/($F30*0.00571))^(1/4)*25.4/1000 -> 16.685095 | S30: =(((24*Input!$G$6*($J30/(2.54)^4))/(($B30/25.4)*($F30*0.00571)))^0.5)*25.4/1000 -> 20.942282 | T30: =((Input!$G$4*($J30/(2.54)^4)*(Input!$G$5))/(17.1*$F30*0.06854))^(1/4)*0.3048 -> 11.949538 | U30: =(((20*Input!$G$6*($J30/(2.54)^4))/(($B30/25.4)*($F30*0.00571)))^0.5)*25.4/1000 -> 19.117601 | V30: =((384*Input!$C$4*$J30*Input!$C$5)/(3*$F30*100000))^(1/4) -> 12.6778 | W30: =(((200*Input!$C$6*($J30))/($B30*($F30)))^0.5) -> 19.117205 | X30: =MIN(L30:W30) -> 11.15788 | Y30: 16 | Z30: 13 | AB30: =Z30/MIN(L30:W30) -> 1.1650958 | AC30: =Y30/X30 -> 1.4339641 | AD30: =Y30/MIN(N30:O30) -> 0.9589496
A31: 16 | B31: 406.4 | C31: XS | D31: 12.7 | E31: 120 | F31: =((3.1428*(B31^2-(B31-2*D31)^2)/4)*7.85/1000)*9.81 -> 1210.1091 | G31: =(3.14*(B31+E31)*E31*Input!C$2/1000000)*9.81 -> 389.15783 | H31: =((3.14*(B31-2*D31)^2)/4*Input!C$3/1000000)*9.81 -> 1117.8631 | I31: =(Input!C$8/1067)*'Bare+Vapour'!B31 -> 6.2845361 | J31: =((3.1428*(B31^4-(B31-(2*D31))^4)/64))/10000 -> 30477.435 | K31: =(Input!C$9*(Input!C$7+I31)*D31^2)/(0.644*F31*((B31/2)*D31)^0.5) -> 29.012036 | L31: =((384*Input!$C$4*$J31*Input!$C$5)/(5*$F31*100000))^(1/4) -> 11.954867 | M31: =((160*Input!$C$6*$J31)/(B31*$F31))^0.5 -> 18.361135 | N31: =((384*Input!$C$4*$J31*Input!$C$5)/(($F31*100000)))^(1/4) -> 17.876696 | O31: =((240*Input!$C$6*$J31)/($B31*$F31))^0.5 -> 22.487706 | P31: =((185*Input!$G$4*($J31/(2.54)^4)*(Input!$G$5))/($F31*0.00571))^(1/4)*25.4/1000 -> 14.893675 | Q31: =(((16*Input!$G$6*($J31/(2.54)^4))/(($B31/25.4)*($F31*0.00571)))^0.5)*25.4/1000 -> 18.361515 | R31: =((384*Input!$G$4*($J31/(2.54)^4)*(Input!$G$5))/($F31*0.00571))^(1/4)*25.4/1000 -> 17.876881 | S31: =(((24*Input!$G$6*($J31/(2.54)^4))/(($B31/25.4)*($F31*0.00571)))^0.5)*25.4/1000 -> 22.488171 | T31: =((Input!$G$4*($J31/(2.54)^4)*(Input!$G$5))/(17.1*$F31*0.06854))^(1/4)*0.3048 -> 12.803071 | U31: =(((20*Input!$G$6*($J31/(2.54)^4))/(($B31/25.4)*($F31*0.00571)))^0.5)*25.4/1000 -> 20.528798 | V31: =((384*Input!$C$4*$J31*Input!$C$5)/(3*$F31*100000))^(1/4) -> 13.583351 | W31: =(((200*Input!$C$6*($J31))/($B31*($F31)))^0.5) -> 20.528373 | X31: =MIN(L31:W31) -> 11.954867 | Y31: 17 | Z31: 14 | AB31: =Z31/MIN(L31:W31) -> 1.1710712 | AC31: =Y31/X31 -> 1.422015 | AD31: =Y31/MIN(N31:O31) -> 0.95095873
A32: 18 | B32: 457.2 | C32: XS | D32: 12.7 | E32: 120 | F32: =((3.1428*(B32^2-(B32-2*D32)^2)/4)*7.85/1000)*9.81 -> 1366.2523 | G32: =(3.14*(B32+E32)*E32*Input!C$2/1000000)*9.81 -> 426.71334 | H32: =((3.14*(B32-2*D32)^2)/4*Input!C$3/1000000)*9.81 -> 1435.833 | I32: =(Input!C$8/1067)*'Bare+Vapour'!B32 -> 7.0701031 | J32: =((3.1428*(B32^4-(B32-(2*D32))^4)/64))/10000 -> 43853.086 | K32: =(Input!C$9*(Input!C$7+I32)*D32^2)/(0.644*F32*((B32/2)*D32)^0.5) -> 24.405838 | L32: =((384*Input!$C$4*$J32*Input!$C$5)/(5*$F32*100000))^(1/4) -> 12.702044 | M32: =((160*Input!$C$6*$J32)/(B32*$F32))^0.5 -> 19.542538 | N32: =((384*Input!$C$4*$J32*Input!$C$5)/(($F32*100000)))^(1/4) -> 18.993985 | O32: =((240*Input!$C$6*$J32)/($B32*$F32))^0.5 -> 23.934623 | P32: =((185*Input!$G$4*($J32/(2.54)^4)*(Input!$G$5))/($F32*0.00571))^(1/4)*25.4/1000 -> 15.824526 | Q32: =(((16*Input!$G$6*($J32/(2.54)^4))/(($B32/25.4)*($F32*0.00571)))^0.5)*25.4/1000 -> 19.542942 | R32: =((384*Input!$G$4*($J32/(2.54)^4)*(Input!$G$5))/($F32*0.00571))^(1/4)*25.4/1000 -> 18.994182 | S32: =(((24*Input!$G$6*($J32/(2.54)^4))/(($B32/25.4)*($F32*0.00571)))^0.5)*25.4/1000 -> 23.935119 | T32: =((Input!$G$4*($J32/(2.54)^4)*(Input!$G$5))/(17.1*$F32*0.06854))^(1/4)*0.3048 -> 13.60326 | U32: =(((20*Input!$G$6*($J32/(2.54)^4))/(($B32/25.4)*($F32*0.00571)))^0.5)*25.4/1000 -> 21.849674 | V32: =((384*Input!$C$4*$J32*Input!$C$5)/(3*$F32*100000))^(1/4) -> 14.432308 | W32: =(((200*Input!$C$6*($J32))/($B32*($F32)))^0.5) -> 21.849222 | X32: =MIN(L32:W32) -> 12.702044 | Y32: 18 | Z32: 14.9 | AB32: =Z32/MIN(L32:W32) -> 1.1730396 | AC32: =Y32/X32 -> 1.4170948 | AD32: =Y32/MIN(N32:O32) -> 0.94766841
A33: 20 | B33: 508 | C33: XS | D33: 12.7 | E33: 140 | F33: =((3.1428*(B33^2-(B33-2*D33)^2)/4)*7.85/1000)*9.81 -> 1522.3954 | G33: =(3.14*(B33+E33)*E33*Input!C$2/1000000)*9.81 -> 558.89689 | H33: =((3.14*(B33-2*D33)^2)/4*Input!C$3/1000000)*9.81 -> 1793.5492 | I33: =(Input!C$8/1067)*'Bare+Vapour'!B33 -> 7.8556701 | J33: =((3.1428*(B33^4-(B33-(2*D33))^4)/64))/10000 -> 60662.583 | K33: =(Input!C$9*(Input!C$7+I33)*D33^2)/(0.644*F33*((B33/2)*D33)^0.5) -> 20.931154 | L33: =((384*Input!$C$4*$J33*Input!$C$5)/(5*$F33*100000))^(1/4) -> 13.407711 | M33: =((160*Input!$C$6*$J33)/(B33*$F33))^0.5 -> 20.65686 | N33: =((384*Input!$C$4*$J33*Input!$C$5)/(($F33*100000)))^(1/4) -> 20.049205 | O33: =((240*Input!$C$6*$J33)/($B33*$F33))^0.5 -> 25.299384 | P33: =((185*Input!$G$4*($J33/(2.54)^4)*(Input!$G$5))/($F33*0.00571))^(1/4)*25.4/1000 -> 16.703665 | Q33: =(((16*Input!$G$6*($J33/(2.54)^4))/(($B33/25.4)*($F33*0.00571)))^0.5)*25.4/1000 -> 20.657288 | R33: =((384*Input!$G$4*($J33/(2.54)^4)*(Input!$G$5))/($F33*0.00571))^(1/4)*25.4/1000 -> 20.049412 | S33: =(((24*Input!$G$6*($J33/(2.54)^4))/(($B33/25.4)*($F33*0.00571)))^0.5)*25.4/1000 -> 25.299907 | T33: =((Input!$G$4*($J33/(2.54)^4)*(Input!$G$5))/(17.1*$F33*0.06854))^(1/4)*0.3048 -> 14.358995 | U33: =(((20*Input!$G$6*($J33/(2.54)^4))/(($B33/25.4)*($F33*0.00571)))^0.5)*25.4/1000 -> 23.09555 | V33: =((384*Input!$C$4*$J33*Input!$C$5)/(3*$F33*100000))^(1/4) -> 15.234101 | W33: =(((200*Input!$C$6*($J33))/($B33*($F33)))^0.5) -> 23.095072 | X33: =MIN(L33:W33) -> 13.407711 | Y33: 19 | Z33: 15.6 | AB33: =Z33/MIN(L33:W33) -> 1.1635096 | AC33: =Y33/X33 -> 1.417095 | AD33: =Y33/MIN(N33:O33) -> 0.94766852
A34: 24 | B34: 609.6 | C34: XS | D34: 12.7 | E34: 140 | F34: =((3.1428*(B34^2-(B34-2*D34)^2)/4)*7.85/1000)*9.81 -> 1834.6816 | G34: =(3.14*(B34+E34)*E34*Input!C$2/1000000)*9.81 -> 646.5264 | H34: =((3.14*(B34-2*D34)^2)/4*Input!C$3/1000000)*9.81 -> 2628.2203 | I34: =(Input!C$8/1067)*'Bare+Vapour'!B34 -> 9.4268041 | J34: =((3.1428*(B34^4-(B34-(2*D34))^4)/64))/10000 -> 106152.88 | K34: =(Input!C$9*(Input!C$7+I34)*D34^2)/(0.644*F34*((B34/2)*D34)^0.5) -> 16.086073 | L34: =((384*Input!$C$4*$J34*Input!$C$5)/(5*$F34*100000))^(1/4) -> 14.718009 | M34: =((160*Input!$C$6*$J34)/(B34*$F34))^0.5 -> 22.722834 | N34: =((384*Input!$C$4*$J34*Input!$C$5)/(($F34*100000)))^(1/4) -> 22.008556 | O34: =((240*Input!$C$6*$J34)/($B34*$F34))^0.5 -> 27.829675 | P34: =((185*Input!$G$4*($J34/(2.54)^4)*(Input!$G$5))/($F34*0.00571))^(1/4)*25.4/1000 -> 18.336066 | Q34: =(((16*Input!$G$6*($J34/(2.54)^4))/(($B34/25.4)*($F34*0.00571)))^0.5)*25.4/1000 -> 22.723304 | R34: =((384*Input!$G$4*($J34/(2.54)^4)*(Input!$G$5))/($F34*0.00571))^(1/4)*25.4/1000 -> 22.008784 | S34: =(((24*Input!$G$6*($J34/(2.54)^4))/(($B34/25.4)*($F34*0.00571)))^0.5)*25.4/1000 -> 27.830251 | T34: =((Input!$G$4*($J34/(2.54)^4)*(Input!$G$5))/(17.1*$F34*0.06854))^(1/4)*0.3048 -> 15.762259 | U34: =(((20*Input!$G$6*($J34/(2.54)^4))/(($B34/25.4)*($F34*0.00571)))^0.5)*25.4/1000 -> 25.405427 | V34: =((384*Input!$C$4*$J34*Input!$C$5)/(3*$F34*100000))^(1/4) -> 16.722886 | W34: =(((200*Input!$C$6*($J34))/($B34*($F34)))^0.5) -> 25.404901 | X34: =MIN(L34:W34) -> 14.718009 | Y34: 21 | Z34: 17.2 | AB34: =Z34/MIN(L34:W34) -> 1.1686364 | AC34: =Y34/X34 -> 1.4268235 | AD34: =Y34/MIN(N34:O34) -> 0.95417436
A35: 1 | B35: 33.4 | C35: 10S | D35: 2.77 | E35: 40 | F35: =((3.1428*(B35^2-(B35-2*D35)^2)/4)*7.85/1000)*9.81 -> 20.534407 | G35: =(3.14*(B35+E35)*E35*Input!C$2/1000000)*9.81 -> 18.087756 | H35: =((3.14*(B35-2*D35)^2)/4*Input!C$3/1000000)*9.81 -> 5.9772427 | I35: =(Input!C$8/1067)*'Bare+Vapour'!B35 -> 0.51649485 | J35: =((3.1428*(B35^4-(B35-(2*D35))^4)/64))/10000 -> 3.1527162 | K35: =(Input!C$9*(Input!C$7+I35)*D35^2)/(0.644*F35*((B35/2)*D35)^0.5) -> 574.52048 | L35: =((384*Input!$C$4*$J35*Input!$C$5)/(5*$F35*100000))^(1/4) -> 3.3404653 | M35: =((160*Input!$C$6*$J35)/(B35*$F35))^0.5 -> 5.0006628 | N35: =((384*Input!$C$4*$J35*Input!$C$5)/(($F35*100000)))^(1/4) -> 4.9951607 | O35: =((240*Input!$C$6*$J35)/($B35*$F35))^0.5 -> 6.1245361 | P35: =((185*Input!$G$4*($J35/(2.54)^4)*(Input!$G$5))/($F35*0.00571))^(1/4)*25.4/1000 -> 4.1616359 | Q35: =(((16*Input!$G$6*($J35/(2.54)^4))/(($B35/25.4)*($F35*0.00571)))^0.5)*25.4/1000 -> 5.0007662 | R35: =((384*Input!$G$4*($J35/(2.54)^4)*(Input!$G$5))/($F35*0.00571))^(1/4)*25.4/1000 -> 4.9952123 | S35: =(((24*Input!$G$6*($J35/(2.54)^4))/(($B35/25.4)*($F35*0.00571)))^0.5)*25.4/1000 -> 6.1246628 | T35: =((Input!$G$4*($J35/(2.54)^4)*(Input!$G$5))/(17.1*$F35*0.06854))^(1/4)*0.3048 -> 3.577473 | U35: =(((20*Input!$G$6*($J35/(2.54)^4))/(($B35/25.4)*($F35*0.00571)))^0.5)*25.4/1000 -> 5.5910266 | V35: =((384*Input!$C$4*$J35*Input!$C$5)/(3*$F35*100000))^(1/4) -> 3.7955013 | W35: =(((200*Input!$C$6*($J35))/($B35*($F35)))^0.5) -> 5.590911 | X35: =MIN(L35:W35) -> 3.3404653 | Y35: 4.5 | Z35: 3.8 | AA35: 5.7 | AB35: =Z35/MIN(L35:W35) -> 1.1375661 | AC35: =Y35/X35 -> 1.3471177 | AD35: =Y35/MIN(N35:O35) -> 0.90087192
A36: 1.5 | B36: 48.26 | C36: 10S | D36: 2.77 | E36: 50 | F36: =((3.1428*(B36^2-(B36-2*D36)^2)/4)*7.85/1000)*9.81 -> 30.496578 | G36: =(3.14*(B36+E36)*E36*Input!C$2/1000000)*9.81 -> 30.267421 | H36: =((3.14*(B36-2*D36)^2)/4*Input!C$3/1000000)*9.81 -> 14.054039 | I36: =(Input!C$8/1067)*'Bare+Vapour'!B36 -> 0.74628866 | J36: =((3.1428*(B36^4-(B36-(2*D36))^4)/64))/10000 -> 10.281623 | K36: =(Input!C$9*(Input!C$7+I36)*D36^2)/(0.644*F36*((B36/2)*D36)^0.5) -> 322.55804 | L36: =((384*Input!$C$4*$J36*Input!$C$5)/(5*$F36*100000))^(1/4) -> 4.066389 | M36: =((160*Input!$C$6*$J36)/(B36*$F36))^0.5 -> 6.1646876 | N36: =((384*Input!$C$4*$J36*Input!$C$5)/(($F36*100000)))^(1/4) -> 6.0806699 | O36: =((240*Input!$C$6*$J36)/($B36*$F36))^0.5 -> 7.5501695 | P36: =((185*Input!$G$4*($J36/(2.54)^4)*(Input!$G$5))/($F36*0.00571))^(1/4)*25.4/1000 -> 5.06601 | Q36: =(((16*Input!$G$6*($J36/(2.54)^4))/(($B36/25.4)*($F36*0.00571)))^0.5)*25.4/1000 -> 6.1648151 | R36: =((384*Input!$G$4*($J36/(2.54)^4)*(Input!$G$5))/($F36*0.00571))^(1/4)*25.4/1000 -> 6.0807328 | S36: =(((24*Input!$G$6*($J36/(2.54)^4))/(($B36/25.4)*($F36*0.00571)))^0.5)*25.4/1000 -> 7.5503257 | T36: =((Input!$G$4*($J36/(2.54)^4)*(Input!$G$5))/(17.1*$F36*0.06854))^(1/4)*0.3048 -> 4.3549015 | U36: =(((20*Input!$G$6*($J36/(2.54)^4))/(($B36/25.4)*($F36*0.00571)))^0.5)*25.4/1000 -> 6.8924728 | V36: =((384*Input!$C$4*$J36*Input!$C$5)/(3*$F36*100000))^(1/4) -> 4.62031 | W36: =(((200*Input!$C$6*($J36))/($B36*($F36)))^0.5) -> 6.8923303 | X36: =MIN(L36:W36) -> 4.066389 | Y36: 5.5 | Z36: 4.7 | AA36: 7 | AB36: =Z36/MIN(L36:W36) -> 1.1558166 | AC36: =Y36/X36 -> 1.3525514 | AD36: =Y36/MIN(N36:O36) -> 0.90450561
A37: 2 | B37: 60.32 | C37: 10S | D37: 2.77 | E37: 50 | F37: =((3.1428*(B37^2-(B37-2*D37)^2)/4)*7.85/1000)*9.81 -> 38.581624 | G37: =(3.14*(B37+E37)*E37*Input!C$2/1000000)*9.81 -> 33.982311 | H37: =((3.14*(B37-2*D37)^2)/4*Input!C$3/1000000)*9.81 -> 23.109083 | I37: =(Input!C$8/1067)*'Bare+Vapour'!B37 -> 0.93278351 | J37: =((3.1428*(B37^4-(B37-(2*D37))^4)/64))/10000 -> 20.789664 | K37: =(Input!C$9*(Input!C$7+I37)*D37^2)/(0.644*F37*((B37/2)*D37)^0.5) -> 228.47815 | L37: =((384*Input!$C$4*$J37*Input!$C$5)/(5*$F37*100000))^(1/4) -> 4.5721769 | M37: =((160*Input!$C$6*$J37)/(B37*$F37))^0.5 -> 6.9711153 | N37: =((384*Input!$C$4*$J37*Input!$C$5)/(($F37*100000)))^(1/4) -> 6.8369992 | O37: =((240*Input!$C$6*$J37)/($B37*$F37))^0.5 -> 8.5378378 | P37: =((185*Input!$G$4*($J37/(2.54)^4)*(Input!$G$5))/($F37*0.00571))^(1/4)*25.4/1000 -> 5.6961333 | Q37: =(((16*Input!$G$6*($J37/(2.54)^4))/(($B37/25.4)*($F37*0.00571)))^0.5)*25.4/1000 -> 6.9712595 | R37: =((384*Input!$G$4*($J37/(2.54)^4)*(Input!$G$5))/($F37*0.00571))^(1/4)*25.4/1000 -> 6.8370699 | S37: =(((24*Input!$G$6*($J37/(2.54)^4))/(($B37/25.4)*($F37*0.00571)))^0.5)*25.4/1000 -> 8.5380144 | T37: =((Input!$G$4*($J37/(2.54)^4)*(Input!$G$5))/(17.1*$F37*0.06854))^(1/4)*0.3048 -> 4.8965753 | U37: =(((20*Input!$G$6*($J37/(2.54)^4))/(($B37/25.4)*($F37*0.00571)))^0.5)*25.4/1000 -> 7.7941051 | V37: =((384*Input!$C$4*$J37*Input!$C$5)/(3*$F37*100000))^(1/4) -> 5.194996 | W37: =(((200*Input!$C$6*($J37))/($B37*($F37)))^0.5) -> 7.7939439 | X37: =MIN(L37:W37) -> 4.5721769 | Y37: 6 | Z37: 5.3 | AA37: 7.9 | AB37: =Z37/MIN(L37:W37) -> 1.1591852 | AC37: =Y37/X37 -> 1.3122852 | AD37: =Y37/MIN(N37:O37) -> 0.87757799 | AE37: =AA37/MIN(R37,P37,N37) -> 1.3869057
